Workbook
Name StartDate: '[1]Title + setup'!$C$8
Name Today: '[1]Action Plan'!$I$2

Sheet Sheet1
A1: HAWB | B1: Docs rcv | C1: 입항보고 | D1: 수입신고 | E1: 수입신고수리 | F1: KPI | G1: Delay Code
A2: 4052648595 | B2: 45404 | C2: 45405.124 | D2: 45405.343 | E2: 45405.385 | F2: =E2-C2 -> 0.26107639
A3: 4052648590 | B3: 45404 | C3: 45405.124 | D3: 45405.349 | E3: 45405.39 | F3: =E3-C3 -> 0.26695602
A4: 4052648602 | B4: 45404 | C4: 45405.422 | D4: 45405.355 | E4: 45405.372 | F4: 00/00:00
A5: 4052648600 | B5: 45404 | C5: 45405.422 | D5: 45405.478 | E5: 45405.664 | F5: =E5-C5 -> 0.24252315
A6: 4397243251 | B6: 45404 | C6: 45405.79 | D6: 45405.786 | E6: 45405.827 | F6: =E6-C6 -> 0.037291667
A7: 4397243252 | B7: 45404 | C7: 45405.79 | D7: 45405.79 | E7: 45405.831 | F7: =E7-C7 -> 0.041377315
A8: 4052648892 | B8: 45406 | C8: 45406.424 | D8: 45406.348 | E8: 45406.373 | F8: 00/00:00
A9: 4120772144 | B9: 45405 | C9: 45406.735 | D9: 45406.585 | E9: 45406.637 | F9: 00/00:00
A10: 4812655987 | B10: 45405 | C10: 45406.814 | D10: 45406.785 | E10: 45406.79 | F10: 00/00:00
A11: 4812657706 | B11: 45405 | C11: 45406.814 | D11: 45406.791 | E11: 45406.828 | F11: =E11-C11 -> 0.014085648
A12: 4812657767 | B12: 45405 | C12: 45406.814 | D12: 45406.831 | E12: 45406.944 | F12: =E12-C12 -> 0.12979167
A13: 4812657717 | B13: 45406 | C13: 45406.814 | D13: 45406.835 | E13: 45406.941 | F13: =E13-C13 -> 0.12684028
A14: 4812657778 | B14: 45405 | C14: 45406.814 | D14: 45406.839 | E14: 45406.938 | F14: =E14-C14 -> 0.12337963
A15: 4812657769 | B15: 45405 | C15: 45406.814 | D15: 45406.85 | E15: 45406.94 | F15: =E15-C15 -> 0.12584491
A16: 4812657435 | B16: 45406 | C16: 45407.463 | D16: 45407.44 | E16: 45407.459 | F16: 00/00:00
A17: 4812657031 | B17: 45406 | C17: 45407.463 | D17: 45407.453 | E17: 45407.494 | F17: =E17-C17 -> 0.031689815
A18: 4812657512 | B18: 45406 | C18: 45407.463 | D18: 45407.445 | E18: 45407.488 | F18: =E18-C18 -> 0.024895833
A19: 4052648950 | B19: 45406 | C19: 45407.503 | D19: 45407.553 | E19: 45407.747 | F19: =E19-C19 -> 0.24395833
A20: 45N0005289 | B20: 45406 | C20: 45407.593 | D20: 45407.556 | E20: 45407.598 | F20: =E20-C20 -> 0.0052662037
A21: 4397243254 | B21: 45406 | C21: 45407.593 | D21: 45407.56 | E21: 45407.602 | F21: =E21-C21 -> 0.0088657407
A22: 4052648594 | B22: 45406 | C22: 45407.747 | D22: 45407.562 | E22: 45407.604 | F22: 00/00:00
A23: 4052648894 | B23: 45406 | C23: 45407.747 | D23: 45407.564 | E23: 45407.606 | F23: 00/00:00
A24: 4812657779 | B24: 45405 | C24: 45406.814 | D24: 45407.632 | E24: 45407.645 | F24: =E24-C24 -> 0.83065972
A25: 11252952 | B25: 45407 | C25: 45407.706 | D25: 45407.706 | E25: 45407.748 | F25: =E25-C25 -> 0.041631944
A26: 11252869 | B26: 45407 | C26: 45407.706 | D26: 45408.32 | E26: 45408.362 | F26: =E26-C26 -> 0.65540509
A27: 11252951 | B27: 45407 | C27: 45407.706 | D27: 45408.321 | E27: 45408.363 | F27: =E27-C27 -> 0.6566088
A28: 11252956 | B28: 45407 | C28: 45407.706 | D28: 45408.322 | E28: 45408.364 | F28: =E28-C28 -> 0.65743056
A29: 11252959 | B29: 45407 | C29: 45407.706 | D29: 45408.323 | E29: 45408.365 | F29: =E29-C29 -> 0.65836806
A30: 11252961 | B30: 45407 | C30: 45407.706 | D30: 45408.323 | E30: 45408.365 | F30: =E30-C30 -> 0.65907407
A31: 11252966 | B31: 45407 | C31: 45407.706 | D31: 45408.324 | E31: 45408.366 | F31: =E31-C31 -> 0.65978009
A32: 4812661170 | B32: 45407 | C32: 45407.835 | D32: 45408.334 | E32: 45408.376 | F32: =E32-C32 -> 0.5405787
A33: 4812657111 | B33: 45407 | C33: 45407.835 | D33: 45408.335 | E33: 45408.377 | F33: =E33-C33 -> 0.54211806
A34: 4812657628 | B34: 45407 | C34: 45408.161 | D34: 45408.401 | E34: 45408.454 | F34: =E34-C34 -> 0.29361111
A35: 4052649298 | B35: 45407 | C35: 45408.456 | D35: 45408.43 | E35: 45408.457 | F35: =E35-C35 -> 0.001099537
A36: 4052649225 | B36: 45407 | C36: 45408.456 | D36: 45408.434 | E36: 45408.454 | F36: 00/00:00
A37: 4052649126 | B37: 45407 | C37: 45408.456 | D37: 45408.439 | E37: 45408.469 | F37: =E37-C37 -> 0.012800926
A38: 11253392 | B38: 45408 | C38: 45408.795 | D38: 45408.764 | E38: 45408.777 | F38: 00/00:00
A39: 11253420 | B39: 45408 | C39: 45408.795 | D39: 45408.765 | E39: 45408.777 | F39: 00/00:00
A40: 11253310 | B40: 45408 | C40: 45408.795 | D40: 45408.768 | E40: 45408.778 | F40: 00/00:00
...

Sheet Import KPI raw data
A1: AMAT Month | B1: Required Day | C1: Differ | D1: Gross Met | E1: Delay Reason | F1: Cont/Uncont | G1: Net Met
A2: FY23 Q4M1 | B2: 0.2 | C2: 2.224 | D2: N | E2: declaration prior to arrival | F2: Uncontrollable | G2: Y
A3: FY23 Q4M1 | B3: 0.2 | C3: -0.053 | D3: Y | G3: Y
A4: FY23 Q4M1 | B4: 0.2 | C4: -0.053 | D4: Y | G4: Y
A5: FY23 Q4M1 | B5: 0.2 | C5: -0.058 | D5: Y | G5: Y
A6: FY23 Q4M1 | B6: 0.2 | C6: 0.278 | D6: N | E6: Documents(Pre-alert) Missing | F6: Uncontrollable | G6: Y
A7: FY23 Q4M1 | B7: 0.2 | C7: 1.86 | D7: N | E7: Customs Broker Off-hour | F7: Uncontrollable | G7: Y
A8: FY23 Q4M1 | B8: 0.2 | C8: 0.478 | D8: N | E8: Customs Broker Off-hour | F8: Uncontrollable | G8: Y
A9: FY23 Q4M1 | B9: 0.2 | C9: 0.312 | D9: N | E9: Documents(Pre-alert) Missing | F9: Uncontrollable | G9: Y
A10: FY23 Q4M1 | B10: 0.2 | C10: 0.641 | D10: N | E10: Customs Broker Off-hour | F10: Uncontrollable | G10: Y
A11: FY23 Q4M1 | B11: 0.2 | C11: 0.641 | D11: N | E11: Customs Broker Off-hour | F11: Uncontrollable | G11: Y
A12: FY23 Q4M1 | B12: 0.2 | C12: 1.607 | D12: N | E12: Delayed submission of import cargo manifests | F12: Uncontrollable | G12: Y
A13: FY23 Q4M1 | B13: 0.2 | C13: 0.529 | D13: N | E13: Required special docs or sample by Customs(Radio Waves Act part, Electrical Appliances Safety Control Act part) | F13: Uncontrollable | G13: Y
A14: FY23 Q4M1 | B14: 0.2 | C14: 2.224 | D14: N | E14: Customs Broker Off-hour | F14: Uncontrollable | G14: Y
A15: FY23 Q4M1 | B15: 0.2 | C15: 0.774 | D15: N | E15: Documents(Pre-alert) Missing | F15: Uncontrollable | G15: Y
A16: FY23 Q4M1 | B16: 0.2 | C16: 1.629 | D16: N | E16: Import & Export (Required submitting documents to customs) | F16: Uncontrollable | G16: Y
A17: FY23 Q4M1 | B17: 0.2 | C17: 1.629 | D17: N | E17: Import & Export (Required submitting documents to customs) | F17: Uncontrollable | G17: Y
... A20: FY23 Q4M1 | B20: 0.2 | C20: 0.275 | D20: N | E20: Documents(Pre-alert) Missing | F20: Uncontrollable | G20: Y
A21: FY23 Q4M1 | B21: 0.2 | C21: -0.123 | D21: Y | G21: Y
A22: FY23 Q4M1 | B22: 0.2 | C22: -0.123 | D22: Y | G22: Y
A23: FY23 Q4M1 | B23: 0.2 | C23: -0.123 | D23: Y | G23: Y
A24: FY23 Q4M1 | B24: 0.2 | C24: 0.641 | D24: N | E24: Import & Export (Required submitting documents to customs) | F24: Uncontrollable | G24: Y
A25: FY23 Q4M1 | B25: 0.2 | C25: 0.641 | D25: N | E25: Documents(Pre-alert) Missing | F25: Uncontrollable | G25: Y
A26: FY23 Q4M1 | B26: 0.2 | C26: 0.641 | D26: N | E26: Customs Broker Off-hour | F26: Uncontrollable | G26: Y
A27: FY23 Q4M1 | B27: 0.2 | C27: 0.641 | D27: N | E27: Documents(Pre-alert) Missing | F27: Uncontrollable | G27: Y
A28: FY23 Q4M1 | B28: 0.2 | C28: 0.641 | D28: N | E28: Customs Broker Off-hour | F28: Uncontrollable | G28: Y
A29: FY23 Q4M1 | B29: 0.2 | C29: 0.774 | D29: N | E29: Documents(Pre-alert) Missing | F29: Uncontrollable | G29: Y
A30: FY23 Q4M1 | B30: 0.2 | C30: 3.198 | D30: N | E30: Customs Broker Off-hour | F30: Uncontrollable | G30: Y
A31: FY23 Q4M1 | B31: 0.2 | C31: 1.843 | D31: N | E31: Required special docs or sample by Customs(Radio Waves Act part, Electrical Appliances Safety Control Act part) | F31: Uncontrollable | G31: Y
A32: FY23 Q4M1 | B32: 0.2 | C32: -0.034 | D32: Y | G32: Y
A33: FY23 Q4M1 | B33: 0.2 | C33: 0.298 | D33: N | E33: declaration prior to arrival | F33: Uncontrollable | G33: Y
A34: FY23 Q4M1 | B34: 0.2 | C34: 1.607 | D34: N | E34: declaration prior to arrival | F34: Uncontrollable | G34: Y
A35: FY23 Q4M1 | B35: 0.2 | C35: 1.607 | D35: N | E35: declaration prior to arrival | F35: Uncontrollable | G35: Y
A36: FY23 Q4M1 | B36: 0.2 | C36: 0.309 | D36: N | E36: Documents(Pre-alert) Missing | F36: Uncontrollable | G36: Y
A37: FY23 Q4M1 | B37: 0.2 | C37: -0.144 | D37: Y | G37: Y
A38: FY23 Q4M1 | B38: 0.2 | C38: -0.093 | D38: Y | G38: Y
A39: FY23 Q4M1 | B39: 0.2 | C39: -0.082 | D39: Y | G39: Y
A40: FY23 Q4M1 | B40: 0.2 | C40: 0.756 | D40: N | E40: declaration prior to arrival | F40: Uncontrollable | G40: Y
A41: FY23 Q4M1 | B41: 0.2 | C41: -0.035 | D41: Y | G41: Y
A42: FY23 Q4M1 | B42: 0.2 | C42: -0.071 | D42: Y | G42: Y
...

Sheet Export KPI (0527-0607)
A1: AMAT WK | B1: AMAT MONTH | C1: Export Declaration Number | D1: Customs(Export) | E1: Customs Inspection or document Received | F1: Normal Export / Re-Export | G1: All Docs Received | H1: Destination Custom Clearance | I1: Submitted to Customs-> Destination Custom Clearance Required Clearance Time | J1: Actual Clearance Time | K1: Diff time | L1: Delay Reason Details | M1: Controllable or Uncontrollable | N1: Net KPI | O1: Gross KPI | P1: Remarks
A2: FY202441 | B2: FY24 Q4M1 | C2: 4388424150553X | D2: Suwon | G2: 45510.417 | H2: 45510.439 | I2: 0.0625 | J2: =H2-G2 -> 0.022222222 | K2: =J2-I2 -> -0.040277778
A3: FY202441 | B3: FY24 Q4M1 | C3: 4388424150554X | D3: Suwon | G3: 45510.417 | H3: 45510.439 | I3: 0.0625 | J3: =H3-G3 -> 0.022222222 | K3: =J3-I3 -> -0.040277778
A4: FY202441 | B4: FY24 Q4M1 | C4: 4388424150555X | D4: Suwon | G4: 45510.417 | H4: 45510.439 | I4: 0.0625 | J4: =H4-G4 -> 0.022222222 | K4: =J4-I4 -> -0.040277778
A5: FY202441 | B5: FY24 Q4M1 | C5: 4388424150556X | D5: Suwon | G5: 45510.417 | H5: 45510.439 | I5: 0.0625 | J5: =H5-G5 -> 0.022222222 | K5: =J5-I5 -> -0.040277778
A6: FY202441 | B6: FY24 Q4M1 | C6: 4388424150557X | D6: Suwon | G6: 45510.417 | H6: 45510.439 | I6: 0.0625 | J6: =H6-G6 -> 0.022222222 | K6: =J6-I6 -> -0.040277778
A7: FY202441 | B7: FY24 Q4M1 | C7: 4388424150558X | D7: Suwon | G7: 45511.455 | H7: 45511.501 | I7: 0.0625 | J7: =H7-G7 -> 0.045833333 | K7: =J7-I7 -> -0.016666667
A8: FY202441 | B8: FY24 Q4M1 | C8: 4388424150559X | D8: Suwon | G8: 45511.455 | H8: 45511.501 | I8: 0.0625 | J8: =H8-G8 -> 0.045833333 | K8: =J8-I8 -> -0.016666667
A9: FY202441 | B9: FY24 Q4M1 | C9: 4388424150560X | D9: Suwon | G9: 45511.455 | H9: 45511.501 | I9: 0.0625 | J9: =H9-G9 -> 0.045833333 | K9: =J9-I9 -> -0.016666667
A10: FY202441 | B10: FY24 Q4M1 | C10: 4388424150561X | D10: Suwon | E10: 화면심사 | G10: 45511.455 | H10: 45511.542 | I10: 0.0625 | J10: =H10-G10 -> 0.086805556 | K10: =J10-I10 -> 0.024305556
A11: FY202441 | B11: FY24 Q4M1 | C11: 4388424150562X | D11: Suwon | G11: 45511.455 | H11: 45511.501 | I11: 0.0625 | J11: =H11-G11 -> 0.045833333 | K11: =J11-I11 -> -0.016666667
A12: FY202441 | B12: FY24 Q4M1 | C12: 4388424150563X | D12: Suwon | G12: 45511.455 | H12: 45511.501 | I12: 0.0625 | J12: =H12-G12 -> 0.045833333 | K12: =J12-I12 -> -0.016666667
A13: FY202441 | B13: FY24 Q4M1 | C13: 4388424150564X | D13: Suwon | G13: 45511.455 | H13: 45511.501 | I13: 0.0625 | J13: =H13-G13 -> 0.045833333 | K13: =J13-I13 -> -0.016666667
A14: FY202441 | B14: FY24 Q4M1 | C14: 4388424150565X | D14: Suwon | F14: 재수출 | G14: 45512.318 | H14: 45512.342 | I14: 0.0625 | J14: =H14-G14 -> 0.023611111 | K14: =J14-I14 -> -0.038888889
A15: FY202441 | B15: FY24 Q4M1 | C15: 4388424150566X | D15: Suwon | G15: 45512.376 | H15: 45512.449 | I15: 0.0625 | J15: =H15-G15 -> 0.072222222 | K15: =J15-I15 -> 0.0097222222
A16: FY202441 | B16: FY24 Q4M1 | C16: 4388424150567X | D16: Suwon | G16: 45512.376 | H16: 45512.449 | I16: 0.0625 | J16: =H16-G16 -> 0.072222222 | K16: =J16-I16 -> 0.0097222222
A17: FY202441 | B17: FY24 Q4M1 | C17: 4388424150569X | D17: Suwon | E17: 서류제출 | G17: 45512.378 | H17: 45512.677 | I17: 0.0625 | J17: =H17-G17 -> 0.29861111 | K17: =J17-I17 -> 0.23611111
A18: FY202441 | B18: FY24 Q4M1 | C18: 4388424150570X | D18: Suwon | G18: 45512.378 | H18: 45512.421 | I18: 0.0625 | J18: =H18-G18 -> 0.042361111 | K18: =J18-I18 -> -0.020138889
A19: FY202441 | B19: FY24 Q4M1 | C19: 4388424150573X | D19: Suwon | G19: 45513.383 | H19: 45513.394 | I19: 0.0625 | J19: =H19-G19 -> 0.011111111 | K19: =J19-I19 -> -0.051388889
A20: FY202441 | B20: FY24 Q4M1 | C20: 4388424150574X | D20: Suwon | G20: 45513.394 | H20: 45513.414 | I20: 0.0625 | J20: =H20-G20 -> 0.020138889 | K20: =J20-I20 -> -0.042361111
A21: FY202441 | B21: FY24 Q4M1 | C21: 4388424150575X | D21: Suwon | G21: 45513.59 | H21: 45513.599 | I21: 0.0625 | J21: =H21-G21 -> 0.0097222222 | K21: =J21-I21 -> -0.052777778
A22: FY202441 | B22: FY24 Q4M1 | C22: 4388424150576X | D22: Suwon | G22: 45513.59 | H22: 45513.599 | I22: 0.0625 | J22: =H22-G22 -> 0.0097222222 | K22: =J22-I22 -> -0.052777778
A23: FY202441 | B23: FY24 Q4M1 | C23: 4388424201315X | D23: Suwon | F23: 재수입 | G23: 45510.375 | H23: 45510.388 | I23: 0.0625 | J23: =H23-G23 -> 0.013194444 | K23: =J23-I23 -> -0.049305556
A24: FY202441 | B24: FY24 Q4M1 | C24: 4388424301831X | D24: Suwon | F24: 재수출 | G24: 45509.375 | H24: 45509.401 | I24: 0.0625 | J24: =H24-G24 -> 0.025694444 | K24: =J24-I24 -> -0.036805556
A25: FY202441 | B25: FY24 Q4M1 | C25: 4388424301832X | D25: Suwon | G25: 45509.375 | H25: 45509.408 | I25: 0.0625 | J25: =H25-G25 -> 0.033333333 | K25: =J25-I25 -> -0.029166667
A26: FY202441 | B26: FY24 Q4M1 | C26: 4388424301833X | D26: Suwon | G26: 45509.375 | H26: 45509.41 | I26: 0.0625 | J26: =H26-G26 -> 0.035416667 | K26: =J26-I26 -> -0.027083333
A27: FY202441 | B27: FY24 Q4M1 | C27: 4388424301834X | D27: Suwon | G27: 45509.375 | H27: 45509.412 | I27: 0.0625 | J27: =H27-G27 -> 0.036805556 | K27: =J27-I27 -> -0.025694444
A28: FY202441 | B28: FY24 Q4M1 | C28: 4388424301835X | D28: Suwon | G28: 45509.375 | H28: 45509.413 | I28: 0.0625 | J28: =H28-G28 -> 0.038194444 | K28: =J28-I28 -> -0.024305556
A29: FY202441 | B29: FY24 Q4M1 | C29: 4388424301836X | D29: Suwon | E29: 화면심사 | G29: 45509.375 | H29: 45509.42 | I29: 0.0625 | J29: =H29-G29 -> 0.045138889 | K29: =J29-I29 -> -0.017361111
A30: FY202441 | B30: FY24 Q4M1 | C30: 4388424301837X | D30: Suwon | G30: 45509.375 | H30: 45509.417 | I30: 0.0625 | J30: =H30-G30 -> 0.041666667 | K30: =J30-I30 -> -0.020833333
A31: FY202441 | B31: FY24 Q4M1 | C31: 4388424301838X | D31: Suwon | F31: 재수입 | G31: 45509.375 | H31: 45509.422 | I31: 0.0625 | J31: =H31-G31 -> 0.047222222 | K31: =J31-I31 -> -0.015277778
A32: FY202441 | B32: FY24 Q4M1 | C32: 4388424301839X | D32: Suwon | G32: 45509.375 | H32: 45509.425 | I32: 0.0625 | J32: =H32-G32 -> 0.05 | K32: =J32-I32 -> -0.0125
A33: FY202441 | B33: FY24 Q4M1 | C33: 4388424301840X | D33: Suwon | G33: 45509.438 | H33: 45509.463 | I33: 0.0625 | J33: =H33-G33 -> 0.025 | K33: =J33-I33 -> -0.0375
A34: FY202441 | B34: FY24 Q4M1 | C34: 4388424301841X | D34: Suwon | E34: 서류제출 | F34: 원상태 | G34: 45509.438 | H34: 45509.632 | I34: 0.0625 | J34: =H34-G34 -> 0.19444444 | K34: =J34-I34 -> 0.13194444
A35: FY202441 | B35: FY24 Q4M1 | C35: 4388424301842X | D35: Suwon | G35: 45509.438 | H35: 45509.466 | I35: 0.0625 | J35: =H35-G35 -> 0.028472222 | K35: =J35-I35 -> -0.034027778
A36: FY202441 | B36: FY24 Q4M1 | C36: 4388424301843X | D36: Suwon | E36: 서류제출 | F36: 원상태 | G36: 45509.438 | H36: 45509.483 | I36: 0.0625 | J36: =H36-G36 -> 0.045138889 | K36: =J36-I36 -> -0.017361111
A37: FY202441 | B37: FY24 Q4M1 | C37: 4388424301844X | D37: Suwon | G37: 45509.438 | H37: 45509.469 | I37: 0.0625 | J37: =H37-G37 -> 0.031944444 | K37: =J37-I37 -> -0.030555556
A38: FY202441 | B38: FY24 Q4M1 | C38: 4388424301845X | D38: Suwon | E38: 서류제출 | G38: 45509.438 | H38: 45509.715 | I38: 0.0625 | J38: =H38-G38 -> 0.27777778 | K38: =J38-I38 -> 0.21527778
A39: FY202441 | B39: FY24 Q4M1 | C39: 4388424301846X | D39: Suwon | G39: 45509.438 | H39: 45509.474 | I39: 0.0625 | J39: =H39-G39 -> 0.036805556 | K39: =J39-I39 -> -0.025694444
A40: FY202441 | B40: FY24 Q4M1 | C40: 4388424301847X | D40: Suwon | E40: 화면심사 | G40: 45509.438 | H40: 45509.572 | I40: 0.0625 | J40: =H40-G40 -> 0.13472222 | K40: =J40-I40 -> 0.072222222
...

Sheet 수출데이터
A1: 5 | B1: 2 | C1: 3 | D1: 4 | E1: 5 | F1: 6 | G1: 7 | H1: 8 | I1: 9 | J1: 10 | K1: 11 | L1: 12 | M1: 13 | N1: 14 | O1: 15 | P1: 16 | Q1: 17 | R1: 18 | S1: 19 | T1: 20 | U1: 21 | V1: 22 | W1: 23 | X1: 24 | Y1: 25 | Z1: 26 | AA1: 27 | AB1: 28 | AC1: 29 | AD1: 30 | AE1: 31 | AF1: 32 | AG1: 33 | AH1: 34 | AI1: 35 | AJ1: 36 | AK1: 37 | AL1: 38 | AM1: 39 | AN1: 40 | AO1: 41 | AP1: 42 | AQ1: 43 | AR1: 44 | AS1: 45 | AT1: 46 | AU1: 47 | AV1: 48 | AW1: 49 | AX1: 50 | AY1: 51 | AZ1: 52 | BA1: 53 | BB1: 54 | BC1: 55 | BD1: 56 | BE1: 57 | BF1: 58 | BG1: 59 | BH1: 60 | BI1: 61 | BJ1: 62 | BK1: 63 | BL1: 64 | BM1: 65 | BN1: 66 | BO1: 67 | BP1: 68 | BQ1: 69 | BR1: 70 | BS1: 71 | BT1: 72 | BU1: 73 | BV1: 74 | BW1: 75 | BX1: 76 | BY1: 77 | BZ1: 78 | CA1: 79 | CB1: 80 | CC1: 81 | CD1: 82 | CE1: 83 | CF1: 84 | CG1: 85 | CH1: 86 | CI1: 87 | CJ1: 88 | CK1: 89 | CL1: 90 | CM1: 91 | CN1: 92 | CO1: 93 | CP1: 94 | CQ1: 95 | CR1: 96 | CS1: 97 | CT1: 98 | CU1: 99 | CV1: 100 | CW1: 101 | CX1: 102 | CY1: 103 | CZ1: 104 | DA1: 105 | DB1: 106 | DC1: 107 | DD1: 108 | DE1: 109 | DF1: 110 | DG1: 111 | DH1: 112 | DI1: 113 | DJ1: 114 | DK1: 115 | DL1: 116 | DM1: 117 | DN1: 118 | DO1: 119 | DP1: 120 | DQ1: 121 | DR1: 122 | DS1: 123 | DT1: 124 | DU1: 125 | DV1: 126 | DW1: 127 | DX1: 128 | DY1: 129 | DZ1: 130 | EA1: 131 | EB1: 132 | EC1: 133 | ED1: 134 | EE1: 135 | EF1: 136 | EG1: 137 | EH1: 138 | EI1: 139 | EJ1: 140 | EK1: 141 | EL1: 142 | EM1: 143 | EN1: 144 | EO1: 145 | EP1: 146 | EQ1: 147 | ER1: 148 | ES1: 149 | ET1: 150 | EU1: 151 | EV1: 152 | EW1: 153 | EX1: 154 | EY1: 155 | EZ1: 156 | FA1: 157 | FB1: 158 | FC1: 159 | FD1: 160 | FE1: 161 | FF1: 162 | FG1: 163 | FH1: 164 | FI1: 165 | FJ1: 166 | FK1: 167 | FL1: 168 | FM1: 169 | FN1: 170 | FO1: 171 | FP1: 172 | FQ1: 173 | FR1: 174 | FS1: 175 | FT1: 176 | FU1: 177
A2: 신고번호 | B2: 세관 | C2: 과 | D2: 신고년 | E2: 신고번호 | F2: 신고체크디지트 | G2: 제출년도 | H2: 제출번호 | I2: 체크디지트 | J2: 신고일자 | K2: 신고구분 | L2: C/S구분 | M2: 거래구분 | N2: 수출종류 | O2: 결제종류 | P2: 신고자 상호 | Q2: 수출대행자 코드 | R2: 수출대행자 상호 | S2: 수출대행자 통관고유부호 | T2: 수출자구분 | U2: 수출화주코드 | V2: 수출화주상호 | W2: 수출화주주소 | X2: 수출화주대표자명 | Y2: 수출화주통관고유부호 | Z2: 수출화주사업번호 | AA2: 수출화주소재지 | AB2: 수출화주 사업장일련번호 | AC2: 제조자 코드 | AD2: 제조자 상호 | AE2: 제조자 주소 | AF2: 제조자 대표자명 | AG2: 제조자 통관고유부호 | AH2: 제조자 사업번호 구분 | AI2: 제조자 사업번호 | AJ2: 제조자 사업장일련번호 | AK2: 해외거래처코드 | AL2: 해외거래처상호 | AM2: 환급신청인 | AN2: 제조장소 | AO2: 환급기관명 | AP2: 목적국코드 | AQ2: 목적국명 | AR2: 적재항 코드 | AS2: 적재항 명 | AT2: 운송형태 | AU2: 운송용기 | AV2: 제조일자 | AW2: 물품소재지 우편번호 | AX2: 물품소재지 주소 | AY2: LC번호 | AZ2: 인보이스 번호 | BA2: 무역업체 참조번호 | BB2: 저장구분 | BC2: 로컬구분 | BD2: 계약번호1 | BE2: 계약번호2 | BF2: 지역구분 | BG2: 총 란수 | BH2: 총중량 | BI2: 중량단위 | BJ2: 총 포장수량 | BK2: USD 환율 | BL2: 총 FOB 원화 | BM2: 총 FOB 달러 | BN2: 인도조건 | BO2: 결제통화단위 | BP2: 결제환율 | BQ2: 입력 결제금액 | BR2: 운임보험료 자동계산여부 | BS2: 운임 통화단위 | BT2: 운임 통화 환율 | BU2: 입력 운임 | BV2: 계산된 운임 원화 | BW2: 보험료 통화단위 | BX2: 보험료 통화 환율 | BY2: 입력 보험료 | BZ2: 계산된 보험료 원화 | CA2: 기타금액 통화단위 | CB2: 기타금액 통화 환율 | CC2: 입력 기타금액 | CD2: 계산된 기타금 원화 | CE2: 운송인 코드 | CF2: 운송인 상호 | CG2: 운송 시작일 | CH2: 운송 종료일 | CI2: 응답형태 | CJ2: 전송구분 | CK2: 세관기재란 | CL2: 수리일 | CM2: 반입지역 | CN2: 전송결과 | CO2: 수신결과 | CP2: 신고서 입력담당자 | CQ2: 장치장 일련번호 | CR2: 대행사 코드 | CS2: 대행사 상호 | CT2: 대행사 사업번호 | CU2: 임시개청여부 | CV2: 반송사유 | CW2: 화물관리번호 전송구분 | CX2: 적재의무기한 | CY2: 관세사실적 | CZ2: 중고여부 | DA2: 팩스 전송결과 | DB2: 간이환급구분 | DC2: 산업단지부호 | DD2: 검사방법 | DE2: 포장단위 | DF2: 신고인기재란 | DG2: 신고인 이름 | DH2: 컨테이너 적입여부 | DI2: 포워드 코드 | DJ2: 포워드 상호 | DK2: 영문 물품소재지 | DL2: 출항일 | DM2: 남북교역여부 | DN2: 선사항공사부호 | DO2: 선사항공사명 | DP2: 선편명 | DQ2: 출항예정일자 | DR2: 적재예정보세구역 | DS2: 장치장부호 | DT2: 반입번호 | DU2: 작성자 | DV2: 선적일자 | DW2: 화물관리번호 | DX2: BL번호 | DY2: 선적여부 | DZ2: 선별결과 | EA2: 물품소재지주소 | EB2: 정정차수 | EC2: 입력자 | ED2: 수리일시 | EE2: 란번호 | EF2: 세번부호 | EG2: 송품장부호 | EH2: 란중량 | EI2: 란중량단위 | EJ2: 란수량 | EK2: 란수량단위 | EL2: 포장수량 | EM2: 포장수량단위 | EN2: 순중량 | EO2: 표준품명 | EP2: 거래품명 | EQ2: 결제금액 | ER2: 결제fob | ES2: FOB원화 | ET2: FOB달러 | EU2: 수입신고번호 | EV2: 수입신고번호란번호 | EW2: 서류첨부여부 | EX2: 상표명 | EY2: 원산지 | EZ2: 원산지결정방법 | FA2: 원산지표시유무 | FB2: 자율원산지증명서발급여부 | FC2: 발급협정코드 | FD2: 철강협회수출승인번호 | FE2: 란번호3 | FF2: 행번호 | FG2: 제품코드 | FH2: 수량 | FI2: 수량단위 | FJ2: 결제금액_1 | FK2: 단가 | FL2: 품명및규격1 | FM2: 품명및규격2 | FN2: 품명및규격3 | FO2: 품명및규격4 | FP2: 품명및규격5 | FQ2: 품명및규격6 | FR2: 품명및규격7 | FS2: 품명및규격8 | FT2: 성분1 | FU2: 성분2 | GA2: 신고번호 | GB2: 신고세관 | GC2: 심사결과 | GD2: 수출구분 | GE2: 서류시간 | GF2: 수리일시 | GI2: 계약번호2
A3: 4388426300422X | B3: 016 | C3: C1 | D3: 26 | E3: 4388426300422X | G3: 2026 | H3: 300422 | I3: X | J3: 20260128 | K3: H | L3: A | M3: 94 | N3: A | O3: GN | P3: 관세법인 정상 경기지사 | Q3: AMAT | R3: 어플라이드머티어리얼즈코리아 | S3: 어플라이1931018 | T3: C | U3: AMAT | V3: 어플라이드머티어리얼즈코리아 | W3: 경기도 성남시 분당구 양현로 322 (코리아디자인센터빌딩5층) | X3: 박광선 | Y3: 어플라이1931018 | Z3: 3128114779 | AA3: 13496 | AB3: 0000 | AC3: 0001 | AD3: 미상 | AG3: 제조미상9999000 | AH3: 01 | AI3: 7701031012021 | AK3: SGAPPLIE0013J | AL3: APPLIED MATERIALSSOUTH EAST ASIA | AM3: 1 | AN3: 13496 | AP3: SG | AQ3: SNGAPOR | AR3: ICN | AS3: 인천공항 | AT3: 40 | AU3: ETC | AV3: 20260128 | AW3: 17554 | AX3: GE 안성 제2공장 | AZ3: KR26010159 | BB3: Y | BD3: DGF/320370 | BE3: 2026-01-28 10:47:18 | BG3: 001 | BH3: 4.5 | BI3: KG | BJ3: 1 | BK3: 1473.06 | BL3: 2464635 | BM3: 1673 | BN3: FCA | BO3: USD | BP3: 1473.06 | BQ3: 1673.14 | BR3: O | BS3: KRW | BT3: 1 | BU3: 0 | BV3: 0 | BW3: USD | BX3: 1473.06 | BY3: 0 | BZ3: 0 | CA3: USD | CB3: 1473.06 | CC3: 0 | CD3: 0 | CI3: AB | CL3: 20260128 | CN3: 완료 | CO3: 수리 | CU3: N | CX3: 20260227 | CZ3: N | DB3: NO | DC3: 999 | DD3: A | DE3: CT | DF3: INV.KR26010159 | DG3: 이성종 | DH3: N | DR3: 04099999 | DU3: 한이진 | DV3: 20260130 | DX3: I262147 | DY3: Y | EA3: 경기도 안성시 원곡 면 성은리 334-1 | EB3: 0 | EC3: 한이진 | ED3: 202601281051 | EE3: 001 | EF3: 9031809091 | EG3: KR26010159 | EH3: 3 | EI3: KG | EJ3: 1 | EK3: U | EL3: 1 | EM3: CT | EN3: 3 | EO3: FOR THE PURPOSE OF SEMICONDUCTOR MANUFACTURING | EP3: MULTIPOLE,TEST FIXTURE | EQ3: 1673.14 | ER3: 1673.14 | ES3: 2464635 | ET3: 1673 | EW3: N | EY3: US | FB3: N | FE3: 001 | FF3: 01 | FH3: 1 | FI3: EA | FJ3: 1673.14 | FK3: 1673.14 | FL3: E11491030 | FM3: MULTIPOLE,TEST FIXTURE | GA3: =A3 -> 4388426300422X | GB3: Seongnam | GC3: =VLOOKUP(L3,수출코드!$A$2:$B$6,2,FALSE) | GD3: =VLOOKUP(M3,수출코드!$E$2:$F$5,2,FALSE) -> 재수출 | GE3: =DATE(LEFT(GI3,4),MID(GI3,5,2),MID(GI3,7,2))+TIME(MID(GI3,10,2),MID(GI3,12,2),"00") -> 45975.658 | GF3: =DATE(LEFT(ED3,4),MID(ED3,5,2),MID(ED3,7,2))+TIME(MID(ED3,9,2),MID(ED3,11,2),"00") -> 46050.452 | GI3: 20251114 154838
A4: 4388426100287X | B4: 021 | C4: D9 | D4: 26 | E4: 4388426100287X | G4: 2026 | H4: 100287 | I4: X | J4: 20260126 | K4: H | L4: P | M4: 11 | N4: A | O4: TT | P4: 관세법인 정상 경기지사 | Q4: AMAT | R4: 어플라이드머티어리얼즈코리아 | S4: 어플라이1931018 | T4: C | U4: AMAT | V4: 어플라이드머티어리얼즈코리아 | W4: 경기도 성남시 분당구 양현로 322 (코리아디자인센터빌딩5층) | X4: 박광선 | Y4: 어플라이1931018 | Z4: 3128114779 | AA4: 13496 | AB4: 0000 | AC4: 0001 | AD4: 미상 | AG4: 제조미상9999000 | AH4: 01 | AI4: 7701031012021 | AK4: USAPPLIE0288X | AL4: APPLIED MATERIALS INC | AM4: 1 | AN4: 13496 | AP4: US | AQ4: U.S.A | AR4: ICN | AS4: 인천공항 | AT4: 40 | AU4: ETC | AV4: 20260126 | AW4: 17118 | AX4: 캔달스퀘어 남사로지스틱스파크 | AZ4: 703681186 | BB4: Y | BD4: DGF/DP04/320268 | BE4: 2026-01-26 08:45:26 | BG4: 015 | BH4: 105 | BI4: KG | BJ4: 10 | BK4: 1473.06 | BL4: 210558781 | BM4: 142940 | BN4: DAP | BO4: USD | BP4: 1473.06 | BQ4: 143917.28 | BR4: O | BS4: KRW | BT4: 1 | BU4: 1440000 | BV4: 1440000 | BW4: USD | BX4: 1473.06 | BY4: 0 | BZ4: 0 | CA4: USD | CB4: 1473.06 | CC4: 0 | CD4: 0 | CI4: AB | CL4: 20260126 | CN4: 완료 | CO4: 수리 | CU4: N | CX4: 20260225 | CZ4: N | DB4: NO | DC4: 999 | DD4: A | DE4: CT | DF4: INV.703681186 | DG4: 이성종 | DH4: N | DR4: 04099999 | DU4: 공통 | DV4: 20260128 | DX4: I229967 | DY4: Y | DZ4: 서류 | EA4: 경기도 용인시 처인구 남사읍 당하로 114 | EB4: 0 | EC4: 공통 | ED4: 202601261057 | EE4: 001 | EF4: 8537105090 | EG4: 703681186 | EH4: 3.45 | EI4: KG | EJ4: 0 | EL4: 10 | EM4: CT | EN4: 3.45 | EO4: BOARDS, PANELS AND CONSOLES FOR ELECTRIC CONTROL | EP4: CONTROL BOX, MOTION, 4 CHANNEL | EQ4: 2636.2 | ER4: 2636.2 | ES4: 3856903 | ET4: 2618 | EW4: N | EY4: US | FB4: N | FE4: 001 | FF4: 01 | FH4: 1 | FI4: EA | FJ4: 2636.2 | FK4: 2636.2 | FL4: 0010-65925B | FM4: CONTROL BOX, MOTION, 4 CHANNEL | GA4: =A4 -> 4388426100287X | GB4: =VLOOKUP(B4,수출코드!$C$2:$D$4,2,FALSE) -> Suwon | GC4: =VLOOKUP(L4,수출코드!$A$2:$B$6,2,FALSE) -> 서류제출 | GD4: =VLOOKUP(M4,수출코드!$E$2:$F$5,2,FALSE) -> 일반 | GE4: =DATE(LEFT(GI4,4),MID(GI4,5,2),MID(GI4,7,2))+TIME(MID(GI4,10,2),MID(GI4,12,2),"00") -> 45975.658 | GF4: =DATE(LEFT(ED4,4),MID(ED4,5,2),MID(ED4,7,2))+TIME(MID(ED4,9,2),MID(ED4,11,2),"00") -> 46048.456 | GI4: 20251114 154838
A5: 4388426100288X | B5: 021 | C5: D9 | D5: 26 | E5: 4388426100288X | G5: 2026 | H5: 100288 | I5: X | J5: 20260126 | K5: H | L5: A | M5: 11 | N5: A | O5: TT | P5: 관세법인 정상 경기지사 | Q5: AMAT | R5: 어플라이드머티어리얼즈코리아 | S5: 어플라이1931018 | T5: C | U5: AMAT | V5: 어플라이드머티어리얼즈코리아 | W5: 경기도 성남시 분당구 양현로 322 (코리아디자인센터빌딩5층) | X5: 박광선 | Y5: 어플라이1931018 | Z5: 3128114779 | AA5: 13496 | AB5: 0000 | AC5: 0001 | AD5: 미상 | AG5: 제조미상9999000 | AH5: 01 | AI5: 7701031012021 | AK5: ILAPPLIE0036D | AL5: APPLIED MATERIALS ISRAEL LTD | AM5: 1 | AN5: 13496 | AP5: IL | AQ5: ISRAEL | AR5: ICN | AS5: 인천공항 | AT5: 40 | AU5: ETC | AV5: 20260126 | AW5: 17118 | AX5: 캔달스퀘어 남사로지스틱스파크 | AZ5: 703681189 | BB5: Y | BD5: DGF/DP04/320268 | BE5: 2026-01-26 08:45:26 | BG5: 005 | BH5: 64 | BI5: KG | BJ5: 5 | BK5: 1473.06 | BL5: 78108069 | BM5: 53024 | BN5: DAP | BO5: USD | BP5: 1473.06 | BQ5: 53554.69 | BR5: O | BS5: KRW | BT5: 1 | BU5: 781200 | BV5: 781200 | BW5: USD | BX5: 1473.06 | BY5: 0 | BZ5: 0 | CA5: USD | CB5: 1473.06 | CC5: 0 | CD5: 0 | CI5: AB | CL5: 20260126 | CN5: 완료 | CO5: 수리 | CU5: N | CX5: 20260225 | CZ5: N | DB5: NO | DC5: 999 | DD5: A | DE5: CT | DF5: INV.703681189 | DG5: 이성종 | DH5: N | DR5: 04099999 | DU5: 공통 | DV5: 20260127 | DX5: I229960 | DY5: Y | EA5: 경기도 용인시 처인구 남사읍 당하로 114 | EB5: 0 | EC5: 공통 | ED5: 202601260926 | EE5: 001 | EF5: 8504409099 | EG5: 703681189 | EH5: 6.312 | EI5: KG | EJ5: 1 | EK5: U | EL5: 5 | EM5: CT | EN5: 6.312 | EO5: STATIC CONVERTERS | EP5: UCPM-14 ASSY, SHVM14 | EQ5: 6134.2 | ER5: 6134.2 | ES5: 8946565 | ET5: 6073 | EW5: N | EY5: IL | FB5: N | FE5: 001 | FF5: 01 | FH5: 1 | FI5: EA | FJ5: 6134.2 | FK5: 6134.2 | FL5: 0090-B8145B | FM5: UCPM-14 ASSY, SHVM14 | GA5: =A5 -> 4388426100288X | GB5: =VLOOKUP(B5,수출코드!$C$2:$D$4,2,FALSE) -> Suwon | GC5: =VLOOKUP(L5,수출코드!$A$2:$B$6,2,FALSE) | GD5: =VLOOKUP(M5,수출코드!$E$2:$F$5,2,FALSE) -> 일반 | GE5: =DATE(LEFT(GI5,4),MID(GI5,5,2),MID(GI5,7,2))+TIME(MID(GI5,10,2),MID(GI5,12,2),"00") -> 45975.658 | GF5: =DATE(LEFT(ED5,4),MID(ED5,5,2),MID(ED5,7,2))+TIME(MID(ED5,9,2),MID(ED5,11,2),"00") -> 46048.393 | GI5: 20251114 154838
A6: 4388426100289X | B6: 021 | C6: D9 | D6: 26 | E6: 4388426100289X | G6: 2026 | H6: 100289 | I6: X | J6: 20260126 | K6: H | L6: A | M6: 11 | N6: A | O6: TT | P6: 관세법인 정상 경기지사 | Q6: AMAT | R6: 어플라이드머티어리얼즈코리아 | S6: 어플라이1931018 | T6: C | U6: AMAT | V6: 어플라이드머티어리얼즈코리아 | W6: 경기도 성남시 분당구 양현로 322 (코리아디자인센터빌딩5층) | X6: 박광선 | Y6: 어플라이1931018 | Z6: 3128114779 | AA6: 13496 | AB6: 0000 | AC6: 0001 | AD6: 미상 | AG6: 제조미상9999000 | AH6: 01 | AI6: 7701031012021 | AK6: USAPPLIE0288X | AL6: APPLIED MATERIALS INC | AM6: 1 | AN6: 13496 | AP6: US | AQ6: U.S.A | AR6: ICN | AS6: 인천공항 | AT6: 40 | AU6: ETC | AV6: 20260126 | AW6: 17118 | AX6: 캔달스퀘어 남사로지스틱스파크 | AZ6: 703681196 | BB6: Y | BD6: DGF/DP04/320268 | BE6: 2026-01-26 08:45:26 | BG6: 001 | BH6: 2 | BI6: KG | BJ6: 1 | BK6: 1473.06 | BL6: 3249900 | BM6: 2206 | BN6: DAP | BO6: USD | BP6: 1473.06 | BQ6: 2238.47 | BR6: O | BS6: KRW | BT6: 1 | BU6: 47500 | BV6: 47500 | BW6: USD | BX6: 1473.06 | BY6: 0 | BZ6: 0 | CA6: USD | CB6: 1473.06 | CC6: 0 | CD6: 0 | CI6: AB | CL6: 20260126 | CN6: 완료 | CO6: 수리 | CU6: N | CX6: 20260225 | CZ6: N | DB6: NO | DC6: 999 | DD6: A | DE6: CT | DF6: INV.703681196 | DG6: 이성종 | DH6: N | DR6: 04099999 | DU6: 공통 | DV6: 20260128 | DX6: I229955 | DY6: Y | EA6: 경기도 용인시 처인구 남사읍 당하로 114 | EB6: 0 | EC6: 공통 | ED6: 202601260926 | EE6: 001 | EF6: 8536909090 | EG6: 703681196 | EH6: 2 | EI6: KG | EJ6: 1 | EK6: U | EL6: 2 | EM6: CT | EN6: 2 | EO6: APPARATUS FOR ELECTRICAL CIRCUITS | EP6: SLIP RING ASSY, ENCLOSED, 8 CIRCUIT | EQ6: 2238.47 | ER6: 2238.47 | ES6: 3249900 | ET6: 2206 | EW6: N | EY6: US | FB6: N | FE6: 001 | FF6: 01 | FH6: 1 | FI6: EA | FJ6: 2238.47 | FK6: 2238.47 | FL6: 0190-75984B | FM6: SLIP RING ASSY, ENCLOSED, 8 CIRCUIT | GA6: =A6 -> 4388426100289X | GB6: =VLOOKUP(B6,수출코드!$C$2:$D$4,2,FALSE) -> Suwon | GC6: =VLOOKUP(L6,수출코드!$A$2:$B$6,2,FALSE) | GD6: =VLOOKUP(M6,수출코드!$E$2:$F$5,2,FALSE) -> 일반 | GE6: =DATE(LEFT(GI6,4),MID(GI6,5,2),MID(GI6,7,2))+TIME(MID(GI6,10,2),MID(GI6,12,2),"00") -> 45975.658 | GF6: =DATE(LEFT(ED6,4),MID(ED6,5,2),MID(ED6,7,2))+TIME(MID(ED6,9,2),MID(ED6,11,2),"00") -> 46048.393 | GI6: 20251114 154838
A7: 4388426100290X | B7: 021 | C7: D9 | D7: 26 | E7: 4388426100290X | G7: 2026 | H7: 100290 | I7: X | J7: 20260126 | K7: H | L7: A | M7: 11 | N7: A | O7: TT | P7: 관세법인 정상 경기지사 | Q7: AMAT | R7: 어플라이드머티어리얼즈코리아 | S7: 어플라이1931018 | T7: C | U7: AMAT | V7: 어플라이드머티어리얼즈코리아 | W7: 경기도 성남시 분당구 양현로 322 (코리아디자인센터빌딩5층) | X7: 박광선 | Y7: 어플라이1931018 | Z7: 3128114779 | AA7: 13496 | AB7: 0000 | AC7: 0001 | AD7: 미상 | AG7: 제조미상9999000 | AH7: 01 | AI7: 7701031012021 | AK7: DEAPPLIE0017M | AL7: APPLIED MATERIALS EUROPE BV | AM7: 1 | AN7: 13496 | AP7: DE | AQ7: GERMANY | AR7: ICN | AS7: 인천공항 | AT7: 40 | AU7: ETC | AV7: 20260126 | AW7: 17118 | AX7: 캔달스퀘어 남사로지스틱스파크 | AZ7: 703684682 | BB7: Y | BD7: DGF/DP01/7057 | BE7: 2026-01-26 11:17:38 | BG7: 001 | BH7: 8 | BI7: KG | BJ7: 1 | BK7: 1473.06 | BL7: 5402042 | BM7: 3667 | BN7: DAP | BO7: USD | BP7: 1473.06 | BQ7: 3739.32 | BR7: O | BS7: KRW | BT7: 1 | BU7: 106200 | BV7: 106200 | BW7: USD | BX7: 1473.06 | BY7: 0 | BZ7: 0 | CA7: USD | CB7: 1473.06 | CC7: 0 | CD7: 0 | CI7: AB | CL7: 20260126 | CN7: 완료 | CO7: 수리 | CU7: N | CX7: 20260225 | CZ7: N | DB7: NO | DC7: 999 | DD7: A | DE7: CT | DF7: INV.703684682 | DG7: 이성종 | DH7: N | DR7: 04099999 | DU7: 공통 | DV7: 20260127 | DX7: I241789 | DY7: Y | EA7: 경기도 용인시 처인구 남사읍 당하로 114 | EB7: 0 | EC7: 공통 | ED7: 202601261133 | EE7: 001 | EF7: 7020001019 | EG7: 703684682 | EH7: 3.45 | EI7: KG | EJ7: 1 | EK7: U | EL7: 1 | EM7: CT | EN7: 3.45 | EO7: OTHER ARTICLES OF GLASS | EP7: SIX ARM SUSCEPTOR SUPPORT SHAFT | EQ7: 3739.32 | ER7: 3739.32 | ES7: 5402042 | ET7: 3667 | EW7: N | EY7: US | FB7: N | FE7: 001 | FF7: 01 | FH7: 1 | FI7: EA | FJ7: 3739.32 | FK7: 3739.32 | FL7: 0200-05388 | FM7: SIX ARM SUSCEPTOR SUPPORT SHAFT | GA7: =A7 -> 4388426100290X | GB7: =VLOOKUP(B7,수출코드!$C$2:$D$4,2,FALSE) -> Suwon | GC7: =VLOOKUP(L7,수출코드!$A$2:$B$6,2,FALSE) | GD7: =VLOOKUP(M7,수출코드!$E$2:$F$5,2,FALSE) -> 일반 | GE7: =DATE(LEFT(GI7,4),MID(GI7,5,2),MID(GI7,7,2))+TIME(MID(GI7,10,2),MID(GI7,12,2),"00") -> 45975.658 | GF7: =DATE(LEFT(ED7,4),MID(ED7,5,2),MID(ED7,7,2))+TIME(MID(ED7,9,2),MID(ED7,11,2),"00") -> 46048.481 | GI7: 20251114 154838
A8: 4388426100291X | B8: 021 | C8: D9 | D8: 26 | E8: 4388426100291X | G8: 2026 | H8: 100291 | I8: X | J8: 20260126 | K8: H | L8: A | M8: 11 | N8: A | O8: TT | P8: 관세법인 정상 경기지사 | Q8: AMAT | R8: 어플라이드머티어리얼즈코리아 | S8: 어플라이1931018 | T8: C | U8: AMAT | V8: 어플라이드머티어리얼즈코리아 | W8: 경기도 성남시 분당구 양현로 322 (코리아디자인센터빌딩5층) | X8: 박광선 | Y8: 어플라이1931018 | Z8: 3128114779 | AA8: 13496 | AB8: 0000 | AC8: 0001 | AD8: 미상 | AG8: 제조미상9999000 | AH8: 01 | AI8: 7701031012021 | AK8: USAPPLIE0161R | AL8: APPLIED MATERIAL INC | AM8: 1 | AN8: 13496 | AP8: US | AQ8: U.S.A | AR8: ICN | AS8: 인천공항 | AT8: 40 | AU8: ETC | AV8: 20260126 | AW8: 17118 | AX8: 캔달스퀘어 남사로지스틱스파크 | AZ8: 703684684 | BB8: Y | BD8: DGF/DP01/7057 | BE8: 2026-01-26 11:17:38 | BG8: 001 | BH8: 1 | BI8: KG | BJ8: 1 | BK8: 1473.06 | BL8: 223475 | BM8: 152 | BN8: DAP | BO8: USD | BP8: 1473.06 | BQ8: 174.45 | BR8: O | BS8: KRW | BT8: 1 | BU8: 33500 | BV8: 33500 | BW8: USD | BX8: 1473.06 | BY8: 0 | BZ8: 0 | CA8: USD | CB8: 1473.06 | CC8: 0 | CD8: 0 | CI8: AB | CL8: 20260126 | CN8: 완료 | CO8: 수리 | CU8: N | CX8: 20260225 | CZ8: N | DB8: NO | DC8: 999 | DD8: A | DE8: CT | DF8: INV.703684684 | DG8: 이성종 | DH8: N | DR8: 04099999 | DU8: 공통 | DV8: 20260127 | DX8: I241786 | DY8: Y | EA8: 경기도 용인시 처인구 남사읍 당하로 114 | EB8: 0 | EC8: 공통 | ED8: 202601261133 | EE8: 001 | EF8: 8544422090 | EG8: 703684684 | EH8: 0.499 | EI8: KG | EJ8: 0 | EL8: 1 | EM8: CT | EN8: 0.499 | EO8: FITTED WITH CONNECTORS PLASTIC INSULATED WIRE | EP8: HARNESS PFG CNTRL, ADIO PFGCONTROL, | EQ8: 174.45 | ER8: 174.45 | ES8: 223475 | ET8: 152 | EW8: N | EY8: US | FB8: N | FE8: 001 | FF8: 01 | FH8: 1 | FI8: EA | FJ8: 174.45 | FK8: 174.45 | FL8: E16417090 | FM8: HARNESS PFG CNTRL, ADIO PFGCONTROL, | GA8: =A8 -> 4388426100291X | GB8: =VLOOKUP(B8,수출코드!$C$2:$D$4,2,FALSE) -> Suwon | GC8: =VLOOKUP(L8,수출코드!$A$2:$B$6,2,FALSE) | GD8: =VLOOKUP(M8,수출코드!$E$2:$F$5,2,FALSE) -> 일반 | GE8: =DATE(LEFT(GI8,4),MID(GI8,5,2),MID(GI8,7,2))+TIME(MID(GI8,10,2),MID(GI8,12,2),"00") -> 45975.658 | GF8: =DATE(LEFT(ED8,4),MID(ED8,5,2),MID(ED8,7,2))+TIME(MID(ED8,9,2),MID(ED8,11,2),"00") -> 46048.481 | GI8: 20251114 154838
A9: 4388426100292X | B9: 021 | C9: D9 | D9: 26 | E9: 4388426100292X | G9: 2026 | H9: 100292 | I9: X | J9: 20260126 | K9: H | L9: A | M9: 11 | N9: A | O9: TT | P9: 관세법인 정상 경기지사 | Q9: AMAT | R9: 어플라이드머티어리얼즈코리아 | S9: 어플라이1931018 | T9: C | U9: AMAT | V9: 어플라이드머티어리얼즈코리아 | W9: 경기도 성남시 분당구 양현로 322 (코리아디자인센터빌딩5층) | X9: 박광선 | Y9: 어플라이1931018 | Z9: 3128114779 | AA9: 13496 | AB9: 0000 | AC9: 0001 | AD9: 미상 | AG9: 제조미상9999000 | AH9: 01 | AI9: 7701031012021 | AK9: CNAPPLIE0052L | AL9: APPLIED MATERIALS SOUTH EAST ASIA PETLTD C/O LIAONING JD LOG | AM9: 1 | AN9: 13496 | AP9: CN | AQ9: PRC | AR9: ICN | AS9: 인천공항 | AT9: 40 | AU9: ETC | AV9: 20260126 | AW9: 17118 | AX9: 캔달스퀘어 남사로지스틱스파크 | AZ9: 703684690 | BB9: Y | BD9: DGF/DP01/7057 | BE9: 2026-01-26 11:17:38 | BG9: 001 | BH9: 4 | BI9: KG | BJ9: 1 | BK9: 1473.06 | BL9: 641678 | BM9: 436 | BN9: DAP | BO9: USD | BP9: 1473.06 | BQ9: 467.38 | BR9: O | BS9: KRW | BT9: 1 | BU9: 46800 | BV9: 46800 | BW9: USD | BX9: 1473.06 | BY9: 0 | BZ9: 0 | CA9: USD | CB9: 1473.06 | CC9: 0 | CD9: 0 | CI9: AB | CL9: 20260126 | CN9: 완료 | CO9: 수리 | CU9: N | CX9: 20260225 | CZ9: N | DB9: NO | DC9: 999 | DD9: A | DE9: CT | DF9: INV.703684690 | DG9: 이성종 | DH9: N | DR9: 04099999 | DU9: 공통 | DV9: 20260127 | DX9: I241783 | DY9: Y | EA9: 경기도 용인시 처인구 남사읍 당하로 114 | EB9: 0 | EC9: 공통 | ED9: 202601261133 | EE9: 001 | EF9: 3917329000 | EG9: 703684690 | EH9: 2.08 | EI9: KG | EJ9: 0 | EL9: 1 | EM9: CT | EN9: 2.08 | EO9: TUBES, PIPES AND HOSES, RIGID | EP9: TBG 1/4 OD 5/32 ID PFA 100MROLL | EQ9: 467.38 | ER9: 467.38 | ES9: 641678 | ET9: 436 | EW9: N | EY9: JP | FB9: N | FE9: 001 | FF9: 01 | FH9: 52 | FI9: M | FJ9: 467.38 | FK9: 8.988 | FL9: 3860-02338 | FM9: TBG 1/4 OD 5/32 ID PFA 100MROLL | GA9: =A9 -> 4388426100292X | GB9: =VLOOKUP(B9,수출코드!$C$2:$D$4,2,FALSE) -> Suwon | GC9: =VLOOKUP(L9,수출코드!$A$2:$B$6,2,FALSE) | GD9: =VLOOKUP(M9,수출코드!$E$2:$F$5,2,FALSE) -> 일반 | GE9: =DATE(LEFT(GI9,4),MID(GI9,5,2),MID(GI9,7,2))+TIME(MID(GI9,10,2),MID(GI9,12,2),"00") -> 45975.658 | GF9: =DATE(LEFT(ED9,4),MID(ED9,5,2),MID(ED9,7,2))+TIME(MID(ED9,9,2),MID(ED9,11,2),"00") -> 46048.481 | GI9: 20251114 154838
A10: 4388426100294X | B10: 021 | C10: D9 | D10: 26 | E10: 4388426100294X | G10: 2026 | H10: 100294 | I10: X | J10: 20260126 | K10: H | L10: A | M10: 11 | N10: A | O10: TT | P10: 관세법인 정상 경기지사 | Q10: AMAT | R10: 어플라이드머티어리얼즈코리아 | S10: 어플라이1931018 | T10: C | U10: AMAT | V10: 어플라이드머티어리얼즈코리아 | W10: 경기도 성남시 분당구 양현로 322 (코리아디자인센터빌딩5층) | X10: 박광선 | Y10: 어플라이1931018 | Z10: 3128114779 | AA10: 13496 | AB10: 0000 | AC10: 0001 | AD10: 미상 | AG10: 제조미상9999000 | AH10: 01 | AI10: 7701031012021 | AK10: DEAPPLIE0017M | AL10: APPLIED MATERIALS EUROPE BV | AM10: 1 | AN10: 13496 | AP10: DE | AQ10: GERMANY | AR10: ICN | AS10: 인천공항 | AT10: 40 | AU10: ETC | AV10: 20260126 | AW10: 17118 | AX10: 캔달스퀘어 남사로지스틱스파크 | AZ10: 703684947 | BB10: Y | BD10: DHL/DP04/7057 | BE10: 2026-01-26 16:19:36 | BG10: 004 | BH10: 32 | BI10: KG | BJ10: 1 | BK10: 1473.06 | BL10: 21701710 | BM10: 14732 | BN10: DAP | BO10: USD | BP10: 1473.06 | BQ10: 14969.46 | BR10: O | BS10: KRW | BT10: 1 | BU10: 349200 | BV10: 349200 | BW10: USD | BX10: 1473.06 | BY10: 0 | BZ10: 0 | CA10: USD | CB10: 1473.06 | CC10: 0 | CD10: 0 | CI10: AB | CL10: 20260126 | CN10: 완료 | CO10: 수리 | CU10: N | CX10: 20260225 | CZ10: N | DB10: NO | DC10: 999 | DD10: A | DE10: CT | DF10: INV.703684947 | DG10: 이성종 | DH10: N | DR10: 04099999 | DU10: 공통 | DV10: 20260128 | DX10: 3250223546 | DY10: Y | EA10: 경기도 용인시 처인구 남사읍 당하로 114 | EB10: 0 | EC10: 공통 | ED10: 202601261643 | EE10: 001 | EF10: 8481801030 | EG10: 703684947 | EH10: 21 | EI10: KG | EJ10: 0 | EL10: 1 | EM10: CT | EN10: 21 | EO10: OTHER AUTOMATICALLY CONTROLLED | EP10: BALL VALVE, PNEU N/C 2.0DIA SST, KF50, 9. | EQ10: 9901.5 | ER10: 9901.5 | ES10: 14354526 | ET10: 9745 | EW10: N | EY10: US | FB10: N | FE10: 001 | FF10: 01 | FH10: 2 | FI10: EA | FJ10: 9901.5 | FK10: 4950.75 | FL10: 0190-53731W | FM10: BALL VALVE, PNEU N/C 2.0DIA SST, KF50, 9. | GA10: =A10 -> 4388426100294X | GB10: =VLOOKUP(B10,수출코드!$C$2:$D$4,2,FALSE) -> Suwon | GC10: =VLOOKUP(L10,수출코드!$A$2:$B$6,2,FALSE) | GD10: =VLOOKUP(M10,수출코드!$E$2:$F$5,2,FALSE) -> 일반 | GE10: =DATE(LEFT(GI10,4),MID(GI10,5,2),MID(GI10,7,2))+TIME(MID(GI10,10,2),MID(GI10,12,2),"00") -> 45975.658 | GF10: =DATE(LEFT(ED10,4),MID(ED10,5,2),MID(ED10,7,2))+TIME(MID(ED10,9,2),MID(ED10,11,2),"00") -> 46048.697 | GI10: 20251114 154838
A11: 4388426100295X | B11: 021 | C11: D9 | D11: 26 | E11: 4388426100295X | G11: 2026 | H11: 100295 | I11: X | J11: 20260126 | K11: H | L11: A | M11: 11 | N11: A | O11: TT | P11: 관세법인 정상 경기지사 | Q11: AMAT | R11: 어플라이드머티어리얼즈코리아 | S11: 어플라이1931018 | T11: C | U11: AMAT | V11: 어플라이드머티어리얼즈코리아 | W11: 경기도 성남시 분당구 양현로 322 (코리아디자인센터빌딩5층) | X11: 박광선 | Y11: 어플라이1931018 | Z11: 3128114779 | AA11: 13496 | AB11: 0000 | AC11: 0001 | AD11: 미상 | AG11: 제조미상9999000 | AH11: 01 | AI11: 7701031012021 | AK11: IEAPPLIE0007G | AL11: APPLIED MATERIALS IRELAND | AM11: 1 | AN11: 13496 | AP11: IE | AQ11: IRELAND | AR11: ICN | AS11: 인천공항 | AT11: 40 | AU11: ETC | AV11: 20260126 | AW11: 17118 | AX11: 캔달스퀘어 남사로지스틱스파크 | AZ11: 703684952 | BB11: Y | BD11: DHL/DP04/7057 | BE11: 2026-01-26 16:19:36 | BG11: 004 | BH11: 35 | BI11: KG | BJ11: 2 | BK11: 1473.06 | BL11: 87959340 | BM11: 59712 | BN11: DAP | BO11: USD | BP11: 1473.06 | BQ11: 60006.07 | BR11: O | BS11: KRW | BT11: 1 | BU11: 433200 | BV11: 433200 | BW11: USD | BX11: 1473.06 | BY11: 0 | BZ11: 0 | CA11: USD | CB11: 1473.06 | CC11: 0 | CD11: 0 | CI11: AB | CL11: 20260126 | CN11: 완료 | CO11: 수리 | CU11: N | CX11: 20260225 | CZ11: N | DB11: NO | DC11: 999 | DD11: A | DE11: CT | DF11: INV.703684952 | DG11: 이성종 | DH11: N | DR11: 04099999 | DU11: 공통 | DV11: 20260128 | DX11: 6575058464 | DY11: Y | EA11: 경기도 용인시 처인구 남사읍 당하로 114 | EB11: 0 | EC11: 공통 | ED11: 202601261643 | EE11: 001 | EF11: 9032894091 | EG11: 703684952 | EH11: 1 | EI11: KG | EJ11: 1 | EK11: U | EL11: 2 | EM11: CT | EN11: 1 | EO11: OF MACHINES FOR MAKING SEMICONDUCTOR DEVICES | EP11: MFC GF120 30SLM O2 1/4VCR MTL N/C 9P-D 4 | EQ11: 2415 | ER11: 2415 | ES11: 3540005 | ET11: 2403 | EW11: N | EY11: US | FB11: N | FE11: 001 | FF11: 01 | FH11: 1 | FI11: EA | FJ11: 2415 | FK11: 2415 | FL11: 3030-16835W | FM11: MFC GF120 30SLM O2 1/4VCR MTL N/C 9P-D 4 | GA11: =A11 -> 4388426100295X | GB11: =VLOOKUP(B11,수출코드!$C$2:$D$4,2,FALSE) -> Suwon | GC11: =VLOOKUP(L11,수출코드!$A$2:$B$6,2,FALSE) | GD11: =VLOOKUP(M11,수출코드!$E$2:$F$5,2,FALSE) -> 일반 | GE11: =DATE(LEFT(GI11,4),MID(GI11,5,2),MID(GI11,7,2))+TIME(MID(GI11,10,2),MID(GI11,12,2),"00") -> 45975.658 | GF11: =DATE(LEFT(ED11,4),MID(ED11,5,2),MID(ED11,7,2))+TIME(MID(ED11,9,2),MID(ED11,11,2),"00") -> 46048.697 | GI11: 20251114 154838
A12: 4388426100296X | B12: 021 | C12: D9 | D12: 26 | E12: 4388426100296X | G12: 2026 | H12: 100296 | I12: X | J12: 20260126 | K12: H | L12: A | M12: 11 | N12: A | O12: TT | P12: 관세법인 정상 경기지사 | Q12: AMAT | R12: 어플라이드머티어리얼즈코리아 | S12: 어플라이1931018 | T12: C | U12: AMAT | V12: 어플라이드머티어리얼즈코리아 | W12: 경기도 성남시 분당구 양현로 322 (코리아디자인센터빌딩5층) | X12: 박광선 | Y12: 어플라이1931018 | Z12: 3128114779 | AA12: 13496 | AB12: 0000 | AC12: 0001 | AD12: 미상 | AG12: 제조미상9999000 | AH12: 01 | AI12: 7701031012021 | AK12: JPAPPLIE0042L | AL12: APPLIED MATERIALS JAPAN INC | AM12: 1 | AN12: 13496 | AP12: JP | AQ12: JAPAN | AR12: ICN | AS12: 인천공항 | AT12: 40 | AU12: ETC | AV12: 20260126 | AW12: 17118 | AX12: 캔달스퀘어 남사로지스틱스파크 | AZ12: 703684953 | BB12: Y | BD12: DHL/DP04/7057 | BE12: 2026-01-26 16:19:36 | BG12: 003 | BH12: 31 | BI12: KG | BJ12: 2 | BK12: 1473.06 | BL12: 41100624 | BM12: 27902 | BN12: DAP | BO12: USD | BP12: 1473.06 | BQ12: 28002.95 | BR12: O | BS12: KRW | BT12: 1 | BU12: 149400 | BV12: 149400 | BW12: USD | BX12: 1473.06 | BY12: 0 | BZ12: 0 | CA12: USD | CB12: 1473.06 | CC12: 0 | CD12: 0 | CI12: AB | CL12: 20260126 | CN12: 완료 | CO12: 수리 | CU12: N | CX12: 20260225 | CZ12: N | DB12: NO | DC12: 999 | DD12: A | DE12: CT | DF12: INV.703684953 | DG12: 이성종 | DH12: N | DR12: 04099999 | DU12: 공통 | DV12: 20260127 | DX12: 6575058766 | DY12: Y | EA12: 경기도 용인시 처인구 남사읍 당하로 114 | EB12: 0 | EC12: 공통 | ED12: 202601261643 | EE12: 001 | EF12: 8501510000 | EG12: 703684953 | EH12: 7 | EI12: KG | EJ12: 1 | EK12: U | EL12: 2 | EM12: CT | EN12: 7 | EO12: MULTI-PHASE AC MOTORS OF AN OUTPUT NOT EXCEEDING 7 | EP12: ACTUATOR SFV | EQ12: 7109.98 | ER12: 7109.98 | ES12: 10435494 | ET12: 7084 | EW12: N | EY12: CH | FB12: N | FE12: 001 | FF12: 01 | FH12: 1 | FI12: EA | FJ12: 7109.98 | FK12: 7109.98 | FL12: 0520-00306W | FM12: ACTUATOR SFV | GA12: =A12 -> 4388426100296X | GB12: =VLOOKUP(B12,수출코드!$C$2:$D$4,2,FALSE) -> Suwon | GC12: =VLOOKUP(L12,수출코드!$A$2:$B$6,2,FALSE) | GD12: =VLOOKUP(M12,수출코드!$E$2:$F$5,2,FALSE) -> 일반 | GE12: =DATE(LEFT(GI12,4),MID(GI12,5,2),MID(GI12,7,2))+TIME(MID(GI12,10,2),MID(GI12,12,2),"00") -> 45971.393 | GF12: =DATE(LEFT(ED12,4),MID(ED12,5,2),MID(ED12,7,2))+TIME(MID(ED12,9,2),MID(ED12,11,2),"00") -> 46048.697 | GI12: 20251110 092628
A13: 4388426100297X | B13: 021 | C13: D9 | D13: 26 | E13: 4388426100297X | G13: 2026 | H13: 100297 | I13: X | J13: 20260126 | K13: H | L13: A | M13: 11 | N13: A | O13: TT | P13: 관세법인 정상 경기지사 | Q13: AMAT | R13: 어플라이드머티어리얼즈코리아 | S13: 어플라이1931018 | T13: C | U13: AMAT | V13: 어플라이드머티어리얼즈코리아 | W13: 경기도 성남시 분당구 양현로 322 (코리아디자인센터빌딩5층) | X13: 박광선 | Y13: 어플라이1931018 | Z13: 3128114779 | AA13: 13496 | AB13: 0000 | AC13: 0001 | AD13: 미상 | AG13: 제조미상9999000 | AH13: 01 | AI13: 7701031012021 | AK13: CNAPPLIE0085Z | AL13: APPLIED MATERIALS SOUTHEAST ASIA PTE LTD CO HEFEI BONDEX FTZ | AM13: 1 | AN13: 13496 | AP13: CN | AQ13: PRC | AR13: ICN | AS13: 인천공항 | AT13: 40 | AU13: ETC | AV13: 20260126 | AW13: 17118 | AX13: 캔달스퀘어 남사로지스틱스파크 | AZ13: 703684954 | BB13: Y | BD13: DHL/DP04/7057 | BE13: 2026-01-26 16:19:36 | BG13: 001 | BH13: 29 | BI13: KG | BJ13: 1 | BK13: 1473.06 | BL13: 18841929 | BM13: 12791 | BN13: DAP | BO13: USD | BP13: 1473.06 | BQ13: 12896.1 | BR13: O | BS13: KRW | BT13: 1 | BU13: 154800 | BV13: 154800 | BW13: USD | BX13: 1473.06 | BY13: 0 | BZ13: 0 | CA13: USD | CB13: 1473.06 | CC13: 0 | CD13: 0 | CI13: AB | CL13: 20260126 | CN13: 완료 | CO13: 수리 | CU13: N | CX13: 20260225 | CZ13: N | DB13: NO | DC13: 999 | DD13: A | DE13: CT | DF13: INV.703684954 | DG13: 이성종 | DH13: N | DR13: 04099999 | DU13: 공통 | DV13: 20260127 | DX13: 6575060225 | DY13: Y | EA13: 경기도 용인시 처인구 남사읍 당하로 114 | EB13: 0 | EC13: 공통 | ED13: 202601261650 | EE13: 001 | EF13: 8504401090 | EG13: 703684954 | EH13: 28 | EI13: KG | EJ13: 1 | EK13: U | EL13: 1 | EM13: CT | EN13: 28 | EO13: OTHER RECTIFIERS AND RECTIFYING APPARATUS | EP13: W',DUAL HV PS -40KVX10+5MA,2MA ISINK | EQ13: 12896.1 | ER13: 12896.1 | ES13: 18841929 | ET13: 12791 | EW13: N | EY13: CN | FB13: N | FE13: 001 | FF13: 01 | FH13: 1 | FI13: EA | FJ13: 12896.1 | FK13: 12896.1 | FL13: E19295184W | FM13: W',DUAL HV PS -40KVX10+5mA,2mA ISINK | GA13: =A13 -> 4388426100297X | GB13: =VLOOKUP(B13,수출코드!$C$2:$D$4,2,FALSE) -> Suwon | GC13: =VLOOKUP(L13,수출코드!$A$2:$B$6,2,FALSE) | GD13: =VLOOKUP(M13,수출코드!$E$2:$F$5,2,FALSE) -> 일반 | GE13: =DATE(LEFT(GI13,4),MID(GI13,5,2),MID(GI13,7,2))+TIME(MID(GI13,10,2),MID(GI13,12,2),"00") -> 45971.393 | GF13: =DATE(LEFT(ED13,4),MID(ED13,5,2),MID(ED13,7,2))+TIME(MID(ED13,9,2),MID(ED13,11,2),"00") -> 46048.701 | GI13: 20251110 092642
A14: 4388426100298X | B14: 021 | C14: D9 | D14: 26 | E14: 4388426100298X | G14: 2026 | H14: 100298 | I14: X | J14: 20260126 | K14: H | L14: A | M14: 11 | N14: A | O14: TT | P14: 관세법인 정상 경기지사 | Q14: AMAT | R14: 어플라이드머티어리얼즈코리아 | S14: 어플라이1931018 | T14: C | U14: AMAT | V14: 어플라이드머티어리얼즈코리아 | W14: 경기도 성남시 분당구 양현로 322 (코리아디자인센터빌딩5층) | X14: 박광선 | Y14: 어플라이1931018 | Z14: 3128114779 | AA14: 13496 | AB14: 0000 | AC14: 0001 | AD14: 미상 | AG14: 제조미상9999000 | AH14: 01 | AI14: 7701031012021 | AK14: CNAPPLIE0052L | AL14: APPLIED MATERIALS SOUTH EAST ASIA PETLTD C/O LIAONING JD LOG | AM14: 1 | AN14: 13496 | AP14: CN | AQ14: PRC | AR14: ICN | AS14: 인천공항 | AT14: 40 | AU14: ETC | AV14: 20260126 | AW14: 17118 | AX14: 캔달스퀘어 남사로지스틱스파크 | AZ14: 703684955 | BB14: Y | BD14: DHL/DP04/7057 | BE14: 2026-01-26 16:19:36 | BG14: 001 | BH14: 1 | BI14: KG | BJ14: 1 | BK14: 1473.06 | BL14: 1180015 | BM14: 801 | BN14: DAP | BO14: USD | BP14: 1473.06 | BQ14: 815.32 | BR14: O | BS14: KRW | BT14: 1 | BU14: 21000 | BV14: 21000 | BW14: USD | BX14: 1473.06 | BY14: 0 | BZ14: 0 | CA14: USD | CB14: 1473.06 | CC14: 0 | CD14: 0 | CI14: AB | CL14: 20260126 | CN14: 완료 | CO14: 수리 | CU14: N | CX14: 20260225 | CZ14: N | DB14: NO | DC14: 999 | DD14: A | DE14: CT | DF14: INV.703684955 | DG14: 이성종 | DH14: N | DR14: 04099999 | DU14: 공통 | DV14: 20260128 | DX14: 6575061010 | DY14: Y | EA14: 경기도 용인시 처인구 남사읍 당하로 114 | EB14: 0 | EC14: 공통 | ED14: 202601261650 | EE14: 001 | EF14: 8516800000 | EG14: 703684955 | EH14: 1 | EI14: KG | EJ14: 1 | EK14: U | EL14: 1 | EM14: CT | EN14: 1 | EO14: ELECTRIC HEATING RESISTORS | EP14: HEATER JACKET, 2ND DIVERT FORELINE, PROD | EQ14: 815.32 | ER14: 815.32 | ES14: 1180015 | ET14: 801 | EW14: N | EY14: VN | FB14: N | FE14: 001 | FF14: 01 | FH14: 1 | FI14: EA | FJ14: 815.32 | FK14: 815.32 | FL14: 0190-49038 | FM14: HEATER JACKET, 2ND DIVERT FORELINE, PROD | GA14: =A14 -> 4388426100298X | GB14: =VLOOKUP(B14,수출코드!$C$2:$D$4,2,FALSE) -> Suwon | GC14: =VLOOKUP(L14,수출코드!$A$2:$B$6,2,FALSE) | GD14: =VLOOKUP(M14,수출코드!$E$2:$F$5,2,FALSE) -> 일반 | GE14: =DATE(LEFT(GI14,4),MID(GI14,5,2),MID(GI14,7,2))+TIME(MID(GI14,10,2),MID(GI14,12,2),"00") -> 45971.415 | GF14: =DATE(LEFT(ED14,4),MID(ED14,5,2),MID(ED14,7,2))+TIME(MID(ED14,9,2),MID(ED14,11,2),"00") -> 46048.701 | GI14: 20251110 095805
A15: 4388426100299X | B15: 021 | C15: D9 | D15: 26 | E15: 4388426100299X | G15: 2026 | H15: 100299 | I15: X | J15: 20260126 | K15: H | L15: A | M15: 11 | N15: A | O15: TT | P15: 관세법인 정상 경기지사 | Q15: AMAT | R15: 어플라이드머티어리얼즈코리아 | S15: 어플라이1931018 | T15: C | U15: AMAT | V15: 어플라이드머티어리얼즈코리아 | W15: 경기도 성남시 분당구 양현로 322 (코리아디자인센터빌딩5층) | X15: 박광선 | Y15: 어플라이1931018 | Z15: 3128114779 | AA15: 13496 | AB15: 0000 | AC15: 0001 | AD15: 미상 | AG15: 제조미상9999000 | AH15: 01 | AI15: 7701031012021 | AK15: CNAPPLIE0103S | AL15: APPLIED MATERIALS SOUTHEAST ASIA PT | AM15: 1 | AN15: 13496 | AP15: CN | AQ15: PRC | AR15: ICN | AS15: 인천공항 | AT15: 40 | AU15: ETC | AV15: 20260126 | AW15: 17118 | AX15: 캔달스퀘어 남사로지스틱스파크 | AZ15: 703684957 | BB15: Y | BD15: DHL/DP04/7057 | BE15: 2026-01-26 16:19:36 | BG15: 002 | BH15: 1 | BI15: KG | BJ15: 1 | BK15: 1473.06 | BL15: 1501112 | BM15: 1019 | BN15: DAP | BO15: USD | BP15: 1473.06 | BQ15: 1033.3 | BR15: O | BS15: KRW | BT15: 1 | BU15: 21000 | BV15: 21000 | BW15: USD | BX15: 1473.06 | BY15: 0 | BZ15: 0 | CA15: USD | CB15: 1473.06 | CC15: 0 | CD15: 0 | CI15: AB | CL15: 20260126 | CN15: 완료 | CO15: 수리 | CU15: N | CX15: 20260225 | CZ15: N | DB15: NO | DC15: 999 | DD15: A | DE15: CT | DF15: INV.703684957 | DG15: 이성종 | DH15: N | DR15: 04099999 | DU15: 공통 | DV15: 20260127 | DX15: 1226420086 | DY15: Y | EA15: 경기도 용인시 처인구 남사읍 당하로 114 | EB15: 0 | EC15: 공통 | ED15: 202601261650 | EE15: 001 | EF15: 7318240000 | EG15: 703684957 | EH15: 0.018 | EI15: KG | EJ15: 0 | EL15: 1 | EM15: CT | EN15: 0.018 | EO15: COTTERS AND COTTER-PINS | EP15: RTNR RING, EXT, SHAFT DIA 5MM, PK 10 | EQ15: 510.05 | ER15: 510.05 | ES15: 740968 | ET15: 503 | EW15: N | EY15: US | FB15: N | FE15: 001 | FF15: 01 | FH15: 18 | FI15: PK | FJ15: 510.05 | FK15: 28.336 | FL15: 3630-00604 | FM15: RTNR RING, EXT, SHAFT DIA 5MM, PK 10 | GA15: =A15 -> 4388426100299X | GB15: =VLOOKUP(B15,수출코드!$C$2:$D$4,2,FALSE) -> Suwon | GC15: =VLOOKUP(L15,수출코드!$A$2:$B$6,2,FALSE) | GD15: =VLOOKUP(M15,수출코드!$E$2:$F$5,2,FALSE) -> 일반 | GE15: =DATE(LEFT(GI15,4),MID(GI15,5,2),MID(GI15,7,2))+TIME(MID(GI15,10,2),MID(GI15,12,2),"00") -> 45971.447 | GF15: =DATE(LEFT(ED15,4),MID(ED15,5,2),MID(ED15,7,2))+TIME(MID(ED15,9,2),MID(ED15,11,2),"00") -> 46048.701 | GI15: 20251110 104435
A16: 4388426100300X | B16: 021 | C16: D9 | D16: 26 | E16: 4388426100300X | G16: 2026 | H16: 100300 | I16: X | J16: 20260126 | K16: H | L16: A | M16: 11 | N16: A | O16: TT | P16: 관세법인 정상 경기지사 | Q16: AMAT | R16: 어플라이드머티어리얼즈코리아 | S16: 어플라이1931018 | T16: C | U16: AMAT | V16: 어플라이드머티어리얼즈코리아 | W16: 경기도 성남시 분당구 양현로 322 (코리아디자인센터빌딩5층) | X16: 박광선 | Y16: 어플라이1931018 | Z16: 3128114779 | AA16: 13496 | AB16: 0000 | AC16: 0001 | AD16: 미상 | AG16: 제조미상9999000 | AH16: 01 | AI16: 7701031012021 | AK16: CNAPPLIE0074D | AL16: APPLIED MATERIALS SOUTH EAST ASIA PTELTD CO WUHAN HMG LOGIST | AM16: 1 | AN16: 13496 | AP16: CN | AQ16: PRC | AR16: ICN | AS16: 인천공항 | AT16: 40 | AU16: ETC | AV16: 20260126 | AW16: 17118 | AX16: 캔달스퀘어 남사로지스틱스파크 | AZ16: 703684958 | BB16: Y | BD16: DHL/DP04/7057 | BE16: 2026-01-26 16:19:36 | BG16: 002 | BH16: 6 | BI16: KG | BJ16: 1 | BK16: 1473.06 | BL16: 4406429 | BM16: 2991 | BN16: DAP | BO16: USD | BP16: 1473.06 | BQ16: 3028.41 | BR16: O | BS16: KRW | BT16: 1 | BU16: 54600 | BV16: 54600 | BW16: USD | BX16: 1473.06 | BY16: 0 | BZ16: 0 | CA16: USD | CB16: 1473.06 | CC16: 0 | CD16: 0 | CI16: AB | CL16: 20260126 | CN16: 완료 | CO16: 수리 | CU16: N | CX16: 20260225 | CZ16: N | DB16: NO | DC16: 999 | DD16: A | DE16: CT | DF16: INV.703684958 | DG16: 이성종 | DH16: N | DR16: 04099999 | DU16: 공통 | DV16: 20260127 | DX16: 1226420613 | DY16: Y | EA16: 경기도 용인시 처인구 남사읍 당하로 114 | EB16: 0 | EC16: 공통 | ED16: 202601261658 | EE16: 001 | EF16: 9001909000 | EG16: 703684958 | EH16: 0.118 | EI16: KG | EJ16: 0 | EL16: 1 | EM16: CT | EN16: 0.118 | EO16: OTHER OPTICAL FIBRES AND OPTICAL FIBRE BUNDLES, CA | EP16: WINDOW QUARTZ UV FILTER LWP 400 CVD | EQ16: 573.16 | ER16: 573.16 | ES16: 833965 | ET16: 566 | EW16: N | EY16: US | FB16: N | FE16: 001 | FF16: 01 | FH16: 1 | FI16: EA | FJ16: 573.16 | FK16: 573.16 | FL16: 0200-74006 | FM16: WINDOW QUARTZ UV FILTER LWP 400 CVD | GA16: =A16 -> 4388426100300X | GB16: =VLOOKUP(B16,수출코드!$C$2:$D$4,2,FALSE) -> Suwon | GC16: =VLOOKUP(L16,수출코드!$A$2:$B$6,2,FALSE) | GD16: =VLOOKUP(M16,수출코드!$E$2:$F$5,2,FALSE) -> 일반 | GE16: =DATE(LEFT(GI16,4),MID(GI16,5,2),MID(GI16,7,2))+TIME(MID(GI16,10,2),MID(GI16,12,2),"00") -> 45971.473 | GF16: =DATE(LEFT(ED16,4),MID(ED16,5,2),MID(ED16,7,2))+TIME(MID(ED16,9,2),MID(ED16,11,2),"00") -> 46048.707 | GI16: 20251110 112108
A17: 4388426100301X | B17: 021 | C17: D9 | D17: 26 | E17: 4388426100301X | G17: 2026 | H17: 100301 | I17: X | J17: 20260126 | K17: H | L17: A | M17: 11 | N17: A | O17: TT | P17: 관세법인 정상 경기지사 | Q17: AMAT | R17: 어플라이드머티어리얼즈코리아 | S17: 어플라이1931018 | T17: C | U17: AMAT | V17: 어플라이드머티어리얼즈코리아 | W17: 경기도 성남시 분당구 양현로 322 (코리아디자인센터빌딩5층) | X17: 박광선 | Y17: 어플라이1931018 | Z17: 3128114779 | AA17: 13496 | AB17: 0000 | AC17: 0001 | AD17: 미상 | AG17: 제조미상9999000 | AH17: 01 | AI17: 7701031012021 | AK17: CNAPPLIE0099S | AL17: APPLIED MATERIALS SOUTHEAST ASIA PTE LTD | AM17: 1 | AN17: 13496 | AP17: CN | AQ17: PRC | AR17: ICN | AS17: 인천공항 | AT17: 40 | AU17: ETC | AV17: 20260126 | AW17: 17118 | AX17: 캔달스퀘어 남사로지스틱스파크 | AZ17: 703684959 | BB17: Y | BD17: DHL/DP04/7057 | BE17: 2026-01-26 16:19:36 | BG17: 001 | BH17: 29 | BI17: KG | BJ17: 1 | BK17: 1473.06 | BL17: 18841929 | BM17: 12791 | BN17: DAP | BO17: USD | BP17: 1473.06 | BQ17: 12896.1 | BR17: O | BS17: KRW | BT17: 1 | BU17: 154800 | BV17: 154800 | BW17: USD | BX17: 1473.06 | BY17: 0 | BZ17: 0 | CA17: USD | CB17: 1473.06 | CC17: 0 | CD17: 0 | CI17: AB | CL17: 20260126 | CN17: 완료 | CO17: 수리 | CU17: N | CX17: 20260225 | CZ17: N | DB17: NO | DC17: 999 | DD17: A | DE17: CT | DF17: INV.703684959 | DG17: 이성종 | DH17: N | DR17: 04099999 | DU17: 공통 | DV17: 20260127 | DX17: 6575063165 | DY17: Y | EA17: 경기도 용인시 처인구 남사읍 당하로 114 | EB17: 0 | EC17: 공통 | ED17: 202601261658 | EE17: 001 | EF17: 8504401090 | EG17: 703684959 | EH17: 28 | EI17: KG | EJ17: 1 | EK17: U | EL17: 1 | EM17: CT | EN17: 28 | EO17: OTHER RECTIFIERS AND RECTIFYING APPARATUS | EP17: W',DUAL HV PS -40KVX10+5MA,2MA ISINK | EQ17: 12896.1 | ER17: 12896.1 | ES17: 18841929 | ET17: 12791 | EW17: N | EY17: MY | FB17: N | FE17: 001 | FF17: 01 | FH17: 1 | FI17: EA | FJ17: 12896.1 | FK17: 12896.1 | FL17: E19295184W | FM17: W',DUAL HV PS -40KVX10+5mA,2mA ISINK | GA17: =A17 -> 4388426100301X | GB17: =VLOOKUP(B17,수출코드!$C$2:$D$4,2,FALSE) -> Suwon | GC17: =VLOOKUP(L17,수출코드!$A$2:$B$6,2,FALSE) | GD17: =VLOOKUP(M17,수출코드!$E$2:$F$5,2,FALSE) -> 일반 | GE17: =DATE(LEFT(GI17,4),MID(GI17,5,2),MID(GI17,7,2))+TIME(MID(GI17,10,2),MID(GI17,12,2),"00") -> 45971.473 | GF17: =DATE(LEFT(ED17,4),MID(ED17,5,2),MID(ED17,7,2))+TIME(MID(ED17,9,2),MID(ED17,11,2),"00") -> 46048.707 | GI17: 20251110 112108
A18: 4388426100302X | B18: 021 | C18: D9 | D18: 26 | E18: 4388426100302X | G18: 2026 | H18: 100302 | I18: X | J18: 20260126 | K18: H | L18: P | M18: 11 | N18: A | O18: TT | P18: 관세법인 정상 경기지사 | Q18: AMAT | R18: 어플라이드머티어리얼즈코리아 | S18: 어플라이1931018 | T18: C | U18: AMAT | V18: 어플라이드머티어리얼즈코리아 | W18: 경기도 성남시 분당구 양현로 322 (코리아디자인센터빌딩5층) | X18: 박광선 | Y18: 어플라이1931018 | Z18: 3128114779 | AA18: 13496 | AB18: 0000 | AC18: 0001 | AD18: 미상 | AG18: 제조미상9999000 | AH18: 01 | AI18: 7701031012021 | AK18: CNAPPLIE0065F | AL18: APPLIED MATERIALS SOUTHEAST ASIA PTE LTD | AM18: 1 | AN18: 13496 | AP18: CN | AQ18: PRC | AR18: ICN | AS18: 인천공항 | AT18: 40 | AU18: ETC | AV18: 20260126 | AW18: 17118 | AX18: 캔달스퀘어 남사로지스틱스파크 | AZ18: 703684960 | BB18: Y | BD18: DHL/DP04/7057 | BE18: 2026-01-26 16:19:36 | BG18: 001 | BH18: 24 | BI18: KG | BJ18: 2 | BK18: 1473.06 | BL18: 46271846 | BM18: 31412 | BN18: DAP | BO18: USD | BP18: 1473.06 | BQ18: 31501.26 | BR18: O | BS18: KRW | BT18: 1 | BU18: 131400 | BV18: 131400 | BW18: USD | BX18: 1473.06 | BY18: 0 | BZ18: 0 | CA18: USD | CB18: 1473.06 | CC18: 0 | CD18: 0 | CI18: AB | CL18: 20260126 | CN18: 완료 | CO18: 수리 | CU18: N | CX18: 20260225 | CZ18: N | DB18: NO | DC18: 999 | DD18: A | DE18: CT | DF18: INV.703684960 | DG18: 이성종 | DH18: N | DR18: 04099999 | DU18: 공통 | DV18: 20260127 | DX18: 6175112414 | DY18: Y | DZ18: 서류 | EA18: 경기도 용인시 처인구 남사읍 당하로 114 | EB18: 0 | EC18: 공통 | ED18: 202601261743 | EE18: 001 | EF18: 8543709090 | EG18: 703684960 | EH18: 17.16 | EI18: KG | EJ18: 2 | EK18: U | EL18: 2 | EM18: CT | EN18: 17.16 | EO18: OTHER ELECTRICAL MACHINES AND APPARATUS | EP18: RF MATCH, 13.56 MHZ, 1.5 KW,85 A, MESA | EQ18: 31501.26 | ER18: 31501.26 | ES18: 46271846 | ET18: 31412 | EW18: N | EY18: CN | FB18: N | FE18: 001 | FF18: 01 | FH18: 2 | FI18: EA | FJ18: 31501.26 | FK18: 15750.63 | FL18: 0190-53531W | FM18: RF MATCH, 13.56 MHZ, 1.5 KW,85 A, MESA | GA18: =A18 -> 4388426100302X | GB18: =VLOOKUP(B18,수출코드!$C$2:$D$4,2,FALSE) -> Suwon | GC18: =VLOOKUP(L18,수출코드!$A$2:$B$6,2,FALSE) -> 서류제출 | GD18: =VLOOKUP(M18,수출코드!$E$2:$F$5,2,FALSE) -> 일반 | GE18: =DATE(LEFT(GI18,4),MID(GI18,5,2),MID(GI18,7,2))+TIME(MID(GI18,10,2),MID(GI18,12,2),"00") -> 45971.473 | GF18: =DATE(LEFT(ED18,4),MID(ED18,5,2),MID(ED18,7,2))+TIME(MID(ED18,9,2),MID(ED18,11,2),"00") -> 46048.738 | GI18: 20251110 112108
A19: 4388426100303X | B19: 021 | C19: D9 | D19: 26 | E19: 4388426100303X | G19: 2026 | H19: 100303 | I19: X | J19: 20260126 | K19: H | L19: A | M19: 11 | N19: A | O19: TT | P19: 관세법인 정상 경기지사 | Q19: AMAT | R19: 어플라이드머티어리얼즈코리아 | S19: 어플라이1931018 | T19: C | U19: AMAT | V19: 어플라이드머티어리얼즈코리아 | W19: 경기도 성남시 분당구 양현로 322 (코리아디자인센터빌딩5층) | X19: 박광선 | Y19: 어플라이1931018 | Z19: 3128114779 | AA19: 13496 | AB19: 0000 | AC19: 0001 | AD19: 미상 | AG19: 제조미상9999000 | AH19: 01 | AI19: 7701031012021 | AK19: DEAPPLIE0017M | AL19: APPLIED MATERIALS EUROPE BV | AM19: 1 | AN19: 13496 | AP19: DE | AQ19: GERMANY | AR19: ICN | AS19: 인천공항 | AT19: 40 | AU19: ETC | AV19: 20260126 | AW19: 17118 | AX19: 캔달스퀘어 남사로지스틱스파크 | AZ19: 703684965 | BB19: Y | BD19: DHL/DP04/7057 | BE19: 2026-01-26 16:19:36 | BG19: 001 | BH19: 1 | BI19: KG | BJ19: 1 | BK19: 1473.06 | BL19: 639129 | BM19: 434 | BN19: DAP | BO19: USD | BP19: 1473.06 | BQ19: 459.54 | BR19: O | BS19: KRW | BT19: 1 | BU19: 37800 | BV19: 37800 | BW19: USD | BX19: 1473.06 | BY19: 0 | BZ19: 0 | CA19: USD | CB19: 1473.06 | CC19: 0 | CD19: 0 | CI19: AB | CL19: 20260126 | CN19: 완료 | CO19: 수리 | CU19: N | CX19: 20260225 | CZ19: N | DB19: NO | DC19: 999 | DD19: A | DE19: CT | DF19: INV.703684965 | DG19: 이성종 | DH19: N | DR19: 04099999 | DU19: 공통 | DV19: 20260128 | DX19: 1226426191 | DY19: Y | EA19: 경기도 용인시 처인구 남사읍 당하로 114 | EB19: 0 | EC19: 공통 | ED19: 202601261705 | EE19: 001 | EF19: 8486902090 | EG19: 703684965 | EH19: 0.33 | EI19: KG | EJ19: 0 | EL19: 1 | EM19: CT | EN19: 0.33 | EO19: PARTS OF MACHINES FOR MAKING SEMICONDUCTOR DEVICES | EP19: SEAL 300MM TITAN PROFILER | EQ19: 459.54 | ER19: 459.54 | ES19: 639129 | ET19: 434 | EW19: N | EY19: JP | FB19: N | FE19: 001 | FF19: 01 | FH19: 11 | FI19: EA | FJ19: 459.54 | FK19: 41.776 | FL19: 0021-42494 | FM19: SEAL 300MM TITAN PROFILER | GA19: =A19 -> 4388426100303X | GB19: =VLOOKUP(B19,수출코드!$C$2:$D$4,2,FALSE) -> Suwon | GC19: =VLOOKUP(L19,수출코드!$A$2:$B$6,2,FALSE) | GD19: =VLOOKUP(M19,수출코드!$E$2:$F$5,2,FALSE) -> 일반 | GE19: =DATE(LEFT(GI19,4),MID(GI19,5,2),MID(GI19,7,2))+TIME(MID(GI19,10,2),MID(GI19,12,2),"00") -> 45971.473 | GF19: =DATE(LEFT(ED19,4),MID(ED19,5,2),MID(ED19,7,2))+TIME(MID(ED19,9,2),MID(ED19,11,2),"00") -> 46048.712 | GI19: 20251110 112138
A20: 4388426100304X | B20: 021 | C20: D9 | D20: 26 | E20: 4388426100304X | G20: 2026 | H20: 100304 | I20: X | J20: 20260126 | K20: H | L20: A | M20: 11 | N20: A | O20: TT | P20: 관세법인 정상 경기지사 | Q20: AMAT | R20: 어플라이드머티어리얼즈코리아 | S20: 어플라이1931018 | T20: C | U20: AMAT | V20: 어플라이드머티어리얼즈코리아 | W20: 경기도 성남시 분당구 양현로 322 (코리아디자인센터빌딩5층) | X20: 박광선 | Y20: 어플라이1931018 | Z20: 3128114779 | AA20: 13496 | AB20: 0000 | AC20: 0001 | AD20: 미상 | AG20: 제조미상9999000 | AH20: 01 | AI20: 7701031012021 | AK20: CNAPPLIE0052L | AL20: APPLIED MATERIALS SOUTH EAST ASIA PETLTD C/O LIAONING JD LOG | AM20: 1 | AN20: 13496 | AP20: CN | AQ20: PRC | AR20: ICN | AS20: 인천공항 | AT20: 40 | AU20: ETC | AV20: 20260126 | AW20: 17118 | AX20: 캔달스퀘어 남사로지스틱스파크 | AZ20: 703684968 | BB20: Y | BD20: DHL/DP04/7057 | BE20: 2026-01-26 16:19:36 | BG20: 002 | BH20: 5 | BI20: KG | BJ20: 1 | BK20: 1473.06 | BL20: 7269455 | BM20: 4935 | BN20: DAP | BO20: USD | BP20: 1473.06 | BQ20: 4969.15 | BR20: O | BS20: KRW | BT20: 1 | BU20: 50400 | BV20: 50400 | BW20: USD | BX20: 1473.06 | BY20: 0 | BZ20: 0 | CA20: USD | CB20: 1473.06 | CC20: 0 | CD20: 0 | CI20: AB | CL20: 20260126 | CN20: 완료 | CO20: 수리 | CU20: N | CX20: 20260225 | CZ20: N | DB20: NO | DC20: 999 | DD20: A | DE20: CT | DF20: INV.703684968 | DG20: 이성종 | DH20: N | DR20: 04099999 | DU20: 공통 | DV20: 20260128 | DX20: 1226427893 | DY20: Y | EA20: 경기도 용인시 처인구 남사읍 당하로 114 | EB20: 0 | EC20: 공통 | ED20: 202601261705 | EE20: 001 | EF20: 8481202000 | EG20: 703684968 | EH20: 2 | EI20: KG | EJ20: 0 | EL20: 1 | EM20: CT | EN20: 2 | EO20: VALVES FOR PNEUMATIC TRANSMISSIONS | EP20: MV-5 | EQ20: 2715.01 | ER20: 2715.01 | ES20: 3971835 | ET20: 2696 | EW20: N | EY20: DE | FB20: N | FE20: 001 | FF20: 01 | FH20: 3 | FI20: EA | FJ20: 2715.01 | FK20: 905.003 | FL20: 0190-A7431 | FM20: MV-5 | GA20: =A20 -> 4388426100304X | GB20: =VLOOKUP(B20,수출코드!$C$2:$D$4,2,FALSE) -> Suwon | GC20: =VLOOKUP(L20,수출코드!$A$2:$B$6,2,FALSE) | GD20: =VLOOKUP(M20,수출코드!$E$2:$F$5,2,FALSE) -> 일반 | GE20: =DATE(LEFT(GI20,4),MID(GI20,5,2),MID(GI20,7,2))+TIME(MID(GI20,10,2),MID(GI20,12,2),"00") -> 45971.473 | GF20: =DATE(LEFT(ED20,4),MID(ED20,5,2),MID(ED20,7,2))+TIME(MID(ED20,9,2),MID(ED20,11,2),"00") -> 46048.712 | GI20: 20251110 112138
